Workbook

Sheet 账单封面
C3: 客户对账单
C5: 947270-FB4-M20260430
D7: 客户代码： | E7: L65EXQC | G7: 客户名称： | H7: SINOWELL TRADING LIMITED
D8: 服务类别： | E8: FB4 | G8: 销售组织： | H8: GFN-总部商务中心
D9: 结算方式： | E9: 月结 | G9: 结算组织： | H9: 4PX DIGITAL PARCEL EXPRESS CO., LIMITED
D10: 结算日： | E10: 2026.05.25 | G10: 账单期间： | H10: 2026.04.01-2026.04.30
C12: 币种维度：
C13: 币种 | D13: 本期消费(-)
C14: EUR | D14: 77457.89 | E14: 0.8501 | F14: =D14/E14
C15: GBP | D15: 14518.28 | E15: 0.7307 | F15: =D15/E15
C16: USD | D16: 5140.96 | E16: 1 | F16: =D16/E16
C17: AUD | D17: 73695.73 | E17: 1.3701 | F17: =D17/E17
C18: CAD | D18: 45484.32 | E18: 1.3508 | F18: =D18/E18
F19: =SUM(F14:F18)
C20: 仓库维度：
C21: 仓库 | F21: 单量 | G21: 币种 | H21: 账单金额 | J21: 含代收代付税费 | L21: 可开票金额
C22: 德国法兰克福2仓 | F22: 98 | G22: EUR | H22: 127.44 | J22: 0 | L22: 127.44
C23: 德国法兰克福1仓 | F23: 7 | G23: EUR | H23: 39.2 | J23: 0 | L23: 39.2
C24: 德国法兰克福2仓 | F24: 8300 | G24: EUR | H24: 42334.58 | J24: 0 | L24: 42334.58
C25: 德国曼海姆1仓 | F25: 3088 | G25: EUR | H25: 15203.1 | J25: 0 | L25: 15203.1
C26: 德国法兰克福2仓 | E26: 请您查收，实际汇率还是按照收汇日当天的汇率~ | F26: 8 | G26: EUR | H26: 5277.99 | J26: 0 | L26: 5277.99
C27: 德国曼海姆1仓 | E27: 入库订单 | F27: 1 | G27: EUR | H27: 7.82 | J27: 0 | L27: 7.82
C28: 德国法兰克福2仓 | E28: 退件订单 | F28: 204 | G28: EUR | H28: 823.49 | J28: 0 | L28: 823.49
C29: 德国曼海姆1仓 | E29: 退件订单 | F29: 33 | G29: EUR | H29: 97.5 | J29: 0 | L29: 97.5
C30: 德国法兰克福2仓 | E30: 仓租 | F30: - | G30: EUR | H30: 10727.21 | J30: 0 | L30: 10727.21
C31: 德国曼海姆1仓 | E31: 仓租 | F31: - | G31: EUR | H31: 2819.56 | J31: 0 | L31: 2819.56
C32: 英国莱斯特1仓 | E32: 增值服务 | F32: 23 | G32: GBP | H32: 26.32 | J32: 0 | L32: 26.32
C33: 英国路腾1仓 | E33: 增值服务 | F33: 1 | G33: GBP | H33: 4.4 | J33: 0 | L33: 4.4
C34: 英国莱斯特1仓 | E34: 出库订单 | F34: 18 | G34: GBP | H34: 52.44 | J34: 0 | L34: 52.44
C35: 英国路腾1仓 | E35: 出库订单 | F35: 2642 | G35: GBP | H35: 6258.91 | J35: 0 | L35: 6258.91
C36: 英国路腾1仓 | E36: 入库订单 | F36: 3 | G36: GBP | H36: 995.7 | J36: 0 | L36: 995.7
C37: 英国莱斯特1仓 | E37: 退件订单 | F37: 36 | G37: GBP | H37: 189.34 | J37: 0 | L37: 189.34
C38: 英国莱斯特1仓 | E38: 仓租 | F38: - | G38: GBP | H38: 54.46 | J38: 0 | L38: 54.46
C39: 英国路腾1仓 | E39: 仓租 | F39: - | G39: GBP | H39: 6936.71 | J39: 0 | L39: 6936.71
C40: 美国休斯顿1仓 | E40: 出库订单 | F40: 7 | G40: USD | H40: 131.02 | J40: 0 | L40: 131.02
C41: 美西洛杉矶3仓 | E41: 出库订单 | F41: 24 | G41: USD | H41: 318.74 | J41: 0 | L41: 318.74
C42: 美东新泽西2仓 | E42: 出库订单 | F42: 201 | G42: USD | H42: 2727.15 | J42: 0 | L42: 2727.15
C43: 澳大利亚悉尼2仓 | E43: 入库订单 | F43: 2 | G43: USD | H43: 0 | J43: 0 | L43: 0
C44: 加拿大温哥华1仓 | E44: 入库订单 | F44: 1 | G44: USD | H44: 0 | J44: 0 | L44: 0
C45: 德国法兰克福2仓 | E45: 入库订单 | F45: 4 | G45: USD | H45: 0 | J45: 0 | L45: 0
...

Sheet 充值退款
A1: 类型 | B1: 入账方式 | C1: 币种 | D1: 金额 | E1: 发生时间 | F1: 交易单据号 | G1: 业务单号 | H1: SKU | I1: SKU数量 | J1: 备注 | K1: SKU英文 | L1: SKU中文 | M1: 客户单号
A2: 充值 | B2: 赔偿 | C2: EUR | D2: 87.33 | E2: 46128.393 | F2: REPA:FB420260407004794:-1 | G2: OC9472702511300291 | J2: 业务单号：OC9472702511300291，尾程问题-轨迹无更新 | M2: 165112024892878992
A3: 充值 | B3: 赔偿 | C3: GBP | D3: 34.99 | E3: 46115.697 | F3: REPA:FB420260402003294:-1 | G3: AJIGBLONA2604020000927 | H3: VSF-AWD4X2-UK | I3: 1 | J3: 业务单号：AJIGBLONA2604020000927，库内问题-遗失 | K3: VIVOSUN AeroWave D4, 4” Grow Tent Clip Fan with Detachable Hook
A4: 充值 | B4: 赔偿 | C4: USD | D4: 9.99 | E4: 46114.575 | F4: REPA:FB420260331000590:-1 | G4: OC9472702602130043 | H4: CFPB-4 | I4: 1 | J4: 业务单号：OC9472702602130043，尾程问题-未上网 | K4: 4 Inch Prefilter for 4" Carbon Filter, Black | L4: 截断款黑色滤芯棉4寸 | M4: 103668522868932608
A5: 充值 | B5: 赔偿 | C5: USD | D5: 13.99 | E5: 46115.696 | F5: REPA:FB420260319011994:-1 | G5: AJIUSNJCB2603190000124 | H5: DWC-0001 | I5: 1 | J5: 业务单号：AJIUSNJCB2603190000124，库内问题-遗失 | K5: DWC Hydroponics Grow System (1 Bucket + Top Drip Kit)
A6: 充值 | B6: 赔偿 | C6: USD | D6: 31.98 | E6: 46115.697 | F6: REPA:FB420260402009389:-1 | G6: AJIUSNJCB2604020000085 | H6: VC-0003 | I6: 2 | J6: 业务单号：AJIUSNJCB2604020000085，库内问题-遗失 | K6: 2Pcs 8" Grow Tent Vent Covers | L6: 8-Inch防尘罩 两个装
A7: 充值 | B7: 赔偿 | C7: USD | D7: 15.99 | E7: 46115.697 | F7: REPA:FB420260402009390:-1 | G7: AJIUSNJCB2604020000086 | H7: VC-0003 | I7: 1 | J7: 业务单号：AJIUSNJCB2604020000086，库内问题-遗失 | K7: 2Pcs 8" Grow Tent Vent Covers | L7: 8-Inch防尘罩 两个装
A8: 充值 | B8: 赔偿 | C8: USD | D8: 39.99 | E8: 46128.395 | F8: REPA:FB420260414003451:-1 | G8: OC9472702603110367 | J8: 业务单号：OC9472702603110367，尾程问题-破损 | M8: 167509242370690461
A9: 充值 | B9: 赔偿 | C9: USD | D9: 17.99 | E9: 46128.397 | F9: REPA:FB420260410000006:-1 | G9: AJIGBLONA2604100000411 | H9: 306109-48C-UK | I9: 1 | J9: 业务单号：AJIGBLONA2604100000411，库内问题-遗失 | K9: VIVOSUN Dryer Vent Hose, 4 inch Aluminum Foil Ducting
A10: 退款 | B10: 赔偿撤销 | C10: USD | D10: -65.99 | E10: 46131.743 | F10: REPA:FB420251010011956:-1 | G10: PAYCN2510100080 | J10: 货已找回并盘盈，需撤销整单货值赔偿 AJIUSNJCB2603240000051
A11: 充值 | B11: 线上 | C11: USD | D11: 175893.45 | E11: 46132.462 | F11: 10010126042065972559
A12: 充值 | B12: 赔偿 | C12: USD | D12: 100 | E12: 46134.493 | F12: REPA:FB420260420004723:-1 | G12: OC9472702603260229 | H12: VSAW200-E42A-UK | I12: 1 | J12: 业务单号：OC9472702603260229，尾程问题-未上网 | K12: AeroLight Wing 200W + E42A | M12: 167855671212031246
A13: 充值 | B13: 赔偿 | C13: USD | D13: 10.99 | E13: 46136.473 | F13: REPA:FB420260420004990:-1 | G13: AJIGBLONA2604200000067 | H13: VC-0002-UK | I13: 1 | J13: 业务单号：AJIGBLONA2604200000067，库内问题-遗失 | K13: 6-Inch防尘罩 两个装 | L13: 6-Inch防尘罩 两个装
A14: 充值 | B14: 赔偿 | C14: USD | D14: 19.99 | E14: 46138.68 | F14: REPA:FB420260422002611:-1 | G14: AJIDEFRAB2604220000014 | H14: VS-TLGG-XL | I14: 1 | J14: 业务单号：AJIDEFRAB2604220000014，库内问题-遗失 | K14: Vivosun Tshirt 2025 Size XL | L14: VS LGGT恤 欧版 XL码
A15: 充值 | B15: 赔偿 | C15: USD | D15: 39.98 | E15: 46138.68 | F15: REPA:FB420260422002621:-1 | G15: AJIDEFRAB2604220000013 | H15: VS-TLGG-XL | I15: 2 | J15: 业务单号：AJIDEFRAB2604220000013，库内问题-遗失 | K15: Vivosun Tshirt 2025 Size XL | L15: VS LGGT恤 欧版 XL码
A16: 充值 | B16: 赔偿 | C16: USD | D16: 100 | E16: 46141.725 | F16: REPA:FB420260427011373:-1 | G16: OC9472702512100008 | H16: VSAW200-E42A-UK | I16: 1 | J16: 业务单号：OC9472702512100008，尾程问题-未上网 | K16: AeroLight Wing 200W + E42A | M16: 165399001454647445
A17: 充值 | B17: 赔偿 | C17: USD | D17: 15.99 | E17: 46141.725 | F17: REPA:FB420260427011383:-1 | G17: OC9472702511160209 | H17: GH-E25-EU | I17: 1 | J17: 业务单号：OC9472702511160209，尾程问题-未上网 | K17: E25控制器-单品包装 | L17: E25控制器-单品包装 | M17: 164834625302991365

Sheet 入库订单
A1: 业务单号 | B1: 客户单号 | C1: 服务类别 | D1: 服务产品 | E1: 下单子账号 | F1: 计费时间 | G1: 计费重 | H1: 实重 | I1: SKU | J1: SKU数量 | K1: 费用类型 | L1: 费用名称 | M1: 币种 | N1: 计费金额 | O1: 优惠金额 | P1: 应收金额 | Q1: 含代收代付税费 | R1: 可开票金额 | S1: 计费单位 | T1: 计费数量 | U1: 计费地点 | V1: 计算公式 | W1: 数字公式 | X1: 报价单编号 | Y1: 优惠券信息 | Z1: 服务商单号 | AA1: 目的地国家 | AB1: 起运地邮编 | AC1: 目的地邮编 | AD1: 起运分区 | AE1: 目的分区 | AF1: 分区名称 | AG1: 有红冲单 | AH1: 划拨单号 | AI1: 是否跨月重计 | AJ1: 备注 | AK1: SKU英文 | AL1: SKU中文 | AM1: 关联入库单号
A2: IC947270260117132 | B2: SW202601150004DE | C2: FB4 | D2: 入库操作费-DE | E2: 947270 | F2: 2026-03-31 17:38:38 | G2: 0 | H2: 10762.26 | I2: VSF-AWA6G2X2-EU | J2: 240 | K2: 入库操作费 | L2: 海外仓查验费 | M2: EUR | N2: 2.75 | O2: 0 | P2: 2.75 | Q2: 0 | R2: 2.75 | U2: 德国法兰克福2仓 | X2: 入库操作费-F230DE-250327（公布价）-3 | AA2: DE | AB2: 65462C | AC2: 65462C | AD2: PZ_国际 | AE2: DEFRAB德国法兰克福2仓 | AK2: 2-Pack AeroWave A6 Gen2 Grow Tent Clip Fan | AL2: 入门款AC电机夹扇A6 Gen2 欧版 两只装
A3: IC947270260117132 | B3: SW202601150004DE | C3: FB4 | D3: 入库操作费-DE | E3: 947270 | F3: 2026-03-31 17:38:38 | G3: 0 | H3: 10762.26 | K3: 入库操作费 | L3: 入库卸货费 | M3: EUR | N3: 348.6 | O3: 0 | P3: 348.6 | Q3: 0 | R3: 348.6 | S3: mums.measurement_info.code.CBM | T3: 67.03768 | U3: 德国法兰克福2仓 | X3: 入库操作费-F230DE-250327（公布价）-3 | AA3: DE | AB3: 65462C | AC3: 65462C | AD3: PZ_国际 | AE3: DEFRAB德国法兰克福2仓
A4: IC947270260117132 | B4: SW202601150004DE | C4: FB4 | D4: 入库操作费-DE | E4: 947270 | F4: 2026-03-31 17:38:38 | G4: 0 | H4: 10762.26 | I4: VSE-ALC08-EU | J4: 180 | K4: 入库操作费 | L4: 入库操作费 | M4: EUR | N4: 432 | O4: 0 | P4: 370.8 | Q4: 0 | R4: 370.8 | S4: 个 | T4: 25.778 | U4: 德国法兰克福2仓 | X4: 入库操作费-F230DE-250327（公布价）-3 | AA4: DE | AB4: 65462C | AC4: 65462C | AD4: PZ_国际 | AE4: DEFRAB德国法兰克福2仓 | AK4: AeroLush Air Conditioner - 8000 BTU - European Standard | AL4: AeroLush 空调_8000BTU_欧规
A5: IC947270260117132 | B5: SW202601150004DE | C5: FB4 | D5: 入库操作费-DE | E5: 947270 | F5: 2026-03-31 17:38:38 | G5: 0 | H5: 10762.26 | I5: VSE-ASH05-EU | J5: 240 | K5: 入库操作费 | L5: 入库操作费 | M5: EUR | N5: 72 | O5: 0 | P5: 62.4 | Q5: 0 | R5: 62.4 | S5: 个 | T5: 1.954 | U5: 德国法兰克福2仓 | X5: 入库操作费-F230DE-250327（公布价）-3 | AA5: DE | AB5: 65462C | AC5: 65462C | AD5: PZ_国际 | AE5: DEFRAB德国法兰克福2仓 | AK5: AeroStream Humidificateur pour plantes 5 l | AL5: AeroStream 5L智能Wi-Fi加湿器（SGS，单核雾化片）-欧版
A6: IC947270260117132 | B6: SW202601150004DE | C6: FB4 | D6: 入库操作费-DE | E6: 947270 | F6: 2026-03-31 17:38:38 | G6: 0 | H6: 10762.26 | I6: VSE-ADD12-EU | J6: 240 | K6: 入库操作费 | L6: 入库操作费 | M6: EUR | N6: 348 | O6: 0 | P6: 300 | Q6: 0 | R6: 300 | S6: 个 | T6: 12.5 | U6: 德国法兰克福2仓 | X6: 入库操作费-F230DE-250327（公布价）-3 | AA6: DE | AB6: 65462C | AC6: 65462C | AD6: PZ_国际 | AE6: DEFRAB德国法兰克福2仓 | AK6: Desumidificador AeroDrain D12 | AL6: AeroDrain WiFi除湿机_12L_欧版
A7: IC947270260117132 | B7: SW202601150004DE | C7: FB4 | D7: 入库操作费-DE | E7: 947270 | F7: 2026-03-31 17:38:38 | G7: 0 | H7: 10762.26 | I7: VG-Y18B-EU | J7: 50 | K7: 入库操作费 | L7: 入库操作费 | M7: EUR | N7: 120 | O7: 0 | P7: 103 | Q7: 0 | R7: 103 | S7: 个 | T7: 23.55 | U7: 德国法兰克福2仓 | X7: 入库操作费-F230DE-250327（公布价）-3 | AA7: DE | AB7: 65462C | AC7: 65462C | AD7: PZ_国际 | AE7: DEFRAB德国法兰克福2仓 | AK7: 欧版 VGrow 智能种植箱 | AL7: 欧版 VGrow 智能种植箱
A8: IC947270260117132 | B8: SW202601150004DE | C8: FB4 | D8: 入库操作费-DE | E8: 947270 | F8: 2026-03-31 17:38:38 | G8: 0 | H8: 10762.26 | I8: 306146-0412-EU | J8: 300 | K8: 入库操作费 | L8: 入库操作费 | M8: EUR | N8: 90 | O8: 0 | P8: 78 | Q8: 0 | R8: 78 | S8: 个 | T8: 2.826 | U8: 德国法兰克福2仓 | X8: 入库操作费-F230DE-250327（公布价）-3 | AA8: DE | AB8: 65462C | AC8: 65462C | AD8: PZ_国际 | AE8: DEFRAB德国法兰克福2仓 | AK8: VIVOSUN钢印滤芯 黑色4" | AL8: VIVOSUN钢印滤芯 黑色4"
A9: IC947270260117132 | B9: SW202601150004DE | C9: FB4 | D9: 入库操作费-DE | E9: 947270 | F9: 2026-03-31 17:38:38 | G9: 0 | H9: 10762.26 | I9: VSF-AWA6G2X2-EU | J9: 240 | K9: 入库操作费 | L9: 入库操作费 | M9: EUR | N9: 72 | O9: 0 | P9: 62.4 | Q9: 0 | R9: 62.4 | S9: 个 | T9: 2.838 | U9: 德国法兰克福2仓 | X9: 入库操作费-F230DE-250327（公布价）-3 | AA9: DE | AB9: 65462C | AC9: 65462C | AD9: PZ_国际 | AE9: DEFRAB德国法兰克福2仓 | AK9: 2-Pack AeroWave A6 Gen2 Grow Tent Clip Fan | AL9: 入门款AC电机夹扇A6 Gen2 欧版 两只装
A10: IC947270260117143 | B10: SW202601150003DE | C10: FB4 | D10: 入库操作费-DE | E10: 947270 | F10: 2026-03-31 15:23:58 | G10: 0 | H10: 9259.808 | I10: VSF-AWA6G2-EU | J10: 240 | K10: 入库操作费 | L10: 海外仓查验费 | M10: EUR | N10: 2.75 | O10: 0 | P10: 2.75 | Q10: 0 | R10: 2.75 | U10: 德国法兰克福2仓 | X10: 入库操作费-F230DE-250327（公布价）-3 | AA10: DE | AB10: 65462C | AC10: 65462C | AD10: PZ_国际 | AE10: DEFRAB德国法兰克福2仓 | AK10: Aerowave A6 Gen2 Grow Tent Clip Fan | AL10: 入门款AC电机夹扇A6 Gen2 欧版
A11: IC947270260117143 | B11: SW202601150003DE | C11: FB4 | D11: 入库操作费-DE | E11: 947270 | F11: 2026-03-31 15:23:58 | G11: 0 | H11: 9259.808 | K11: 入库操作费 | L11: 入库卸货费 | M11: EUR | N11: 317.89 | O11: 0 | P11: 317.89 | Q11: 0 | R11: 317.89 | S11: mums.measurement_info.code.CBM | T11: 61.13187 | U11: 德国法兰克福2仓 | X11: 入库操作费-F230DE-250327（公布价）-3 | AA11: DE | AB11: 65462C | AC11: 65462C | AD11: PZ_国际 | AE11: DEFRAB德国法兰克福2仓
A12: IC947270260117143 | B12: SW202601150003DE | C12: FB4 | D12: 入库操作费-DE | E12: 947270 | F12: 2026-03-31 15:23:58 | G12: 0 | H12: 9259.808 | I12: VSL-LRUC100-EU | J12: 96 | K12: 入库操作费 | L12: 入库操作费 | M12: EUR | N12: 28.8 | O12: 0 | P12: 24.96 | Q12: 0 | R12: 24.96 | S12: 个 | T12: 2.9 | U12: 德国法兰克福2仓 | X12: 入库操作费-F230DE-250327（公布价）-3 | AA12: DE | AB12: 65462C | AC12: 65462C | AD12: PZ_国际 | AE12: DEFRAB德国法兰克福2仓 | AK12: Supplemental light LumaRay-under canopy 100W-EU | AL12: Supplemental light LumaRay-under canopy 100W-EU
A13: IC947270260117143 | B13: SW202601150003DE | C13: FB4 | D13: 入库操作费-DE | E13: 947270 | F13: 2026-03-31 15:23:58 | G13: 0 | H13: 9259.808 | I13: VG-Y18B-EU | J13: 25 | K13: 入库操作费 | L13: 入库操作费 | M13: EUR | N13: 60 | O13: 0 | P13: 51.5 | Q13: 0 | R13: 51.5 | S13: 个 | T13: 23.55 | U13: 德国法兰克福2仓 | X13: 入库操作费-F230DE-250327（公布价）-3 | AA13: DE | AB13: 65462C | AC13: 65462C | AD13: PZ_国际 | AE13: DEFRAB德国法兰克福2仓 | AK13: 欧版 VGrow 智能种植箱 | AL13: 欧版 VGrow 智能种植箱
A14: IC947270260117143 | B14: SW202601150003DE | C14: FB4 | D14: 入库操作费-DE | E14: 947270 | F14: 2026-03-31 15:23:58 | G14: 0 | H14: 9259.808 | I14: VSVC-AZT6E42AP-EU | J14: 25 | K14: 入库操作费 | L14: 入库操作费 | M14: EUR | N14: 23.5 | O14: 0 | P14: 20.25 | Q14: 0 | R14: 20.25 | S14: 个 | T14: 10 | U14: 德国法兰克福2仓 | X14: 入库操作费-F230DE-250327（公布价）-3 | AA14: DE | AB14: 65462C | AC14: 65462C | AD14: PZ_国际 | AE14: DEFRAB德国法兰克福2仓 | AK14: Smart Air Filtration Kit Pro 6″ | AL14: AeroZesh T6 金属底座风机 6寸 + GrowHub E42A+控制器+黑色滤芯6寸+黑色风管6寸8ft 欧版
A15: IC947270260117143 | B15: SW202601150003DE | C15: FB4 | D15: 入库操作费-DE | E15: 947270 | F15: 2026-03-31 15:23:58 | G15: 0 | H15: 9259.808 | I15: VSF-AWD4X2-EU | J15: 432 | K15: 入库操作费 | L15: 入库操作费 | M15: EUR | N15: 116.64 | O15: 0 | P15: 99.36 | Q15: 0 | R15: 99.36 | S15: 个 | T15: 0.61 | U15: 德国法兰克福2仓 | X15: 入库操作费-F230DE-250327（公布价）-3 | AA15: DE | AB15: 65462C | AC15: 65462C | AD15: PZ_国际 | AE15: DEFRAB德国法兰克福2仓 | AK15: AeroWave D4, 4” Grow Tent Clip Fan with Detachable Hook
A16: IC947270260117143 | B16: SW202601150003DE | C16: FB4 | D16: 入库操作费-DE | E16: 947270 | F16: 2026-03-31 15:23:58 | G16: 0 | H16: 9259.808 | I16: VSE-ATW70-EU | J16: 72 | K16: 入库操作费 | L16: 入库操作费 | M16: EUR | N16: 34.56 | O16: 0 | P16: 29.52 | Q16: 0 | R16: 29.52 | S16: 个 | T16: 3.216 | U16: 德国法兰克福2仓 | X16: 入库操作费-F230DE-250327（公布价）-3 | AA16: DE | AB16: 65462C | AC16: 65462C | AD16: PZ_国际 | AE16: DEFRAB德国法兰克福2仓 | AK16: AeroFlux Heater 70w | AL16: AeroFlux Heater 70w
A17: IC947270260117143 | B17: SW202601150003DE | C17: FB4 | D17: 入库操作费-DE | E17: 947270 | F17: 2026-03-31 15:23:58 | G17: 0 | H17: 9259.808 | I17: VSF-AWA6G2-EU | J17: 240 | K17: 入库操作费 | L17: 入库操作费 | M17: EUR | N17: 72 | O17: 0 | P17: 62.4 | Q17: 0 | R17: 62.4 | S17: 个 | T17: 1.468 | U17: 德国法兰克福2仓 | X17: 入库操作费-F230DE-250327（公布价）-3 | AA17: DE | AB17: 65462C | AC17: 65462C | AD17: PZ_国际 | AE17: DEFRAB德国法兰克福2仓 | AK17: Aerowave A6 Gen2 Grow Tent Clip Fan | AL17: 入门款AC电机夹扇A6 Gen2 欧版
A18: IC947270260117143 | B18: SW202601150003DE | C18: FB4 | D18: 入库操作费-DE | E18: 947270 | F18: 2026-03-31 15:23:58 | G18: 0 | H18: 9259.808 | I18: VSVC-AZG4E42AP-EU | J18: 36 | K18: 入库操作费 | L18: 入库操作费 | M18: EUR | N18: 33.84 | O18: 0 | P18: 29.16 | Q18: 0 | R18: 29.16 | S18: 个 | T18: 7 | U18: 德国法兰克福2仓 | X18: 入库操作费-F230DE-250327（公布价）-3 | AA18: DE | AB18: 65462C | AC18: 65462C | AD18: PZ_国际 | AE18: DEFRAB德国法兰克福2仓 | AK18: Smart Air Filtration PRO G4 Kit 4" | AL18: AeroZesh G4 金属底座风机 4寸 + GrowHub E42A+控制器+黑色滤芯4寸+黑色风管4寸8ft 欧版
A19: IC947270260117143 | B19: SW202601150003DE | C19: FB4 | D19: 入库操作费-DE | E19: 947270 | F19: 2026-03-31 15:23:58 | G19: 0 | H19: 9259.808 | I19: VSF-AWE6-G2-EU | J19: 336 | K19: 入库操作费 | L19: 入库操作费 | M19: EUR | N19: 100.8 | O19: 0 | P19: 87.36 | Q19: 0 | R19: 87.36 | S19: 个 | T19: 1.1 | U19: 德国法兰克福2仓 | X19: 入库操作费-F230DE-250327（公布价）-3 | AA19: DE | AB19: 65462C | AC19: 65462C | AD19: PZ_国际 | AE19: DEFRAB德国法兰克福2仓 | AK19: AeroWave E6 Grow Tent Fan 6”
A20: IC947270260117143 | B20: SW202601150003DE | C20: FB4 | D20: 入库操作费-DE | E20: 947270 | F20: 2026-03-31 15:23:58 | G20: 0 | H20: 9259.808 | I20: 304113-52-EU | J20: 32 | K20: 入库操作费 | L20: 入库操作费 | M20: EUR | N20: 46.4 | O20: 0 | P20: 40 | Q20: 0 | R20: 40 | S20: 个 | T20: 11.821 | U20: 德国法兰克福2仓 | X20: 入库操作费-F230DE-250327（公布价）-3 | AA20: DE | AB20: 65462C | AC20: 65462C | AD20: PZ_国际 | AE20: DEFRAB德国法兰克福2仓 | AK20: 52帐篷-60"x32"x80"/150*80*200cm 16mm管径 | AL20: 52帐篷-60"x32"x80"/150*80*200cm 16mm管径
A21: IC947270260117143 | B21: SW202601150003DE | C21: FB4 | D21: 入库操作费-DE | E21: 947270 | F21: 2026-03-31 15:23:58 | G21: 0 | H21: 9259.808 | I21: E331903J-EU | J21: 36 | K21: 入库操作费 | L21: 入库操作费 | M21: EUR | N21: 33.84 | O21: 0 | P21: 29.16 | Q21: 0 | R21: 29.16 | S21: 个 | T21: 6.262 | U21: 德国法兰克福2仓 | X21: 入库操作费-F230DE-250327（公布价）-3 | AA21: DE | AB21: 65462C | AC21: 65462C | AD21: PZ_国际 | AE21: DEFRAB德国法兰克福2仓 | AK21: E331903J || New lawn mower 16" (with orange flower trimmer) | AL21: E331903J||新款 割草机16"（带橘色花枝剪）
A22: IC947270260117143 | B22: SW202601150003DE | C22: FB4 | D22: 入库操作费-DE | E22: 947270 | F22: 2026-03-31 15:23:58 | G22: 0 | H22: 9259.808 | I22: VSK-GIYS336-EU | J22: 20 | K22: 入库操作费 | L22: 入库操作费 | M22: EUR | N22: 48 | O22: 0 | P22: 41.2 | Q22: 0 | R22: 41.2 | S22: 个 | T22: 23 | U22: 德国法兰克福2仓 | X22: 入库操作费-F230DE-250327（公布价）-3 | AA22: DE | AB22: 65462C | AC22: 65462C | AD22: PZ_国际 | AE22: DEFRAB德国法兰克福2仓 | AK22: Smart Grow Tent Kit GIY-SE-33 3x3, 3-Plant Complete System | AL22: GIY SGS智能标准款帐篷套装S336欧版
A23: IC947270260117143 | B23: SW202601150003DE | C23: FB4 | D23: 入库操作费-DE | E23: 947270 | F23: 2026-03-31 15:23:58 | G23: 0 | H23: 9259.808 | I23: VSE-ASH05-EU | J23: 120 | K23: 入库操作费 | L23: 入库操作费 | M23: EUR | N23: 36 | O23: 0 | P23: 31.2 | Q23: 0 | R23: 31.2 | S23: 个 | T23: 1.954 | U23: 德国法兰克福2仓 | X23: 入库操作费-F230DE-250327（公布价）-3 | AA23: DE | AB23: 65462C | AC23: 65462C | AD23: PZ_国际 | AE23: DEFRAB德国法兰克福2仓 | AK23: AeroStream Humidificateur pour plantes 5 l | AL23: AeroStream 5L智能Wi-Fi加湿器（SGS，单核雾化片）-欧版
A24: IC947270260117143 | B24: SW202601150003DE | C24: FB4 | D24: 入库操作费-DE | E24: 947270 | F24: 2026-03-31 15:23:58 | G24: 0 | H24: 9259.808 | I24: VSE-ASH09-EU | J24: 168 | K24: 入库操作费 | L24: 入库操作费 | M24: EUR | N24: 80.64 | O24: 0 | P24: 68.88 | Q24: 0 | R24: 68.88 | S24: 个 | T24: 3.346 | U24: 德国法兰克福2仓 | X24: 入库操作费-F230DE-250327（公布价）-3 | AA24: DE | AB24: 65462C | AC24: 65462C | AD24: PZ_国际 | AE24: DEFRAB德国法兰克福2仓 | AK24: AeroStream - Humidificador para plantas (9 L) | AL24: AeroStream 9L智能Wi-Fi加湿器（SGS，单核雾化片）-欧版
A25: IC947270260117143 | B25: SW202601150003DE | C25: FB4 | D25: 入库操作费-DE | E25: 947270 | F25: 2026-03-31 15:23:58 | G25: 0 | H25: 9259.808 | I25: VSI-FFSW6-4-EU | J25: 120 | K25: 入库操作费 | L25: 入库操作费 | M25: EUR | N25: 57.6 | O25: 0 | P25: 49.2 | Q25: 0 | R25: 49.2 | S25: 个 | T25: 4.72 | U25: 德国法兰克福2仓 | X25: 入库操作费-F230DE-250327（公布价）-3 | AA25: DE | AB25: 65462C | AC25: 65462C | AD25: PZ_国际 | AE25: DEFRAB德国法兰克福2仓 | AK25: 4-Pack FlexFeed Self-Watering Irrigation Pot
A26: IC947270260117143 | B26: SW202601150003DE | C26: FB4 | D26: 入库操作费-DE | E26: 947270 | F26: 2026-03-31 15:23:58 | G26: 0 | H26: 9259.808 | I26: VST-SP2-GL-EU | J26: 200 | K26: 入库操作费 | L26: 入库操作费 | M26: EUR | N26: 60 | O26: 0 | P26: 52 | Q26: 0 | R26: 52 | S26: 个 | T26: 2.014 | U26: 德国法兰克福2仓 | X26: 入库操作费-F230DE-250327（公布价）-3 | AA26: DE | AB26: 65462C | AC26: 65462C | AD26: PZ_国际 | AE26: DEFRAB德国法兰克福2仓 | AK26: Grow Tent High CFM Kit 100-150cm | AL26: 帐篷伸缩支撑杆100-150cm
A27: IC947270260117143 | B27: SW202601150003DE | C27: FB4 | D27: 入库操作费-DE | E27: 947270 | F27: 2026-03-31 15:23:58 | G27: 0 | H27: 9259.808 | I27: VSFL6450-EU | J27: 15 | K27: 入库操作费 | L27: 入库操作费 | M27: EUR | N27: 14.1 | O27: 0 | P27: 12.15 | Q27: 0 | R27: 12.15 | S27: 个 | T27: 10 | U27: 德国法兰克福2仓 | X27: 入库操作费-F230DE-250327（公布价）-3 | AA27: DE | AB27: 65462C | AC27: 65462C | AD27: PZ_国际 | AE27: DEFRAB德国法兰克福2仓 | AK27: LED Grow Light
A28: IC947270260117143 | B28: SW202601150003DE | C28: FB4 | D28: 入库操作费-DE | E28: 947270 | F28: 2026-03-31 15:23:58 | G28: 0 | H28: 9259.808 | I28: VSEX-HID1-ST-EU | J28: 88 | K28: 入库操作费 | L28: 入库操作费 | M28: EUR | N28: 42.24 | O28: 0 | P28: 36.08 | Q28: 0 | R28: 36.08 | S28: 个 | T28: 3.812 | U28: 德国法兰克福2仓 | X28: 入库操作费-F230DE-250327（公布价）-3 | AA28: DE | AB28: 65462C | AC28: 65462C | AD28: PZ_国际 | AE28: DEFRAB德国法兰克福2仓 | AK28: Herbal Decarboxylation and Infusion Machine | AL28: S4508B 黄油机套装-欧版
A29: IC947270260117143 | B29: SW202601150003DE | C29: FB4 | D29: 入库操作费-DE | E29: 947270 | F29: 2026-03-31 15:23:58 | G29: 0 | H29: 9259.808 | I29: VSE-ADD12-EU | J29: 50 | K29: 入库操作费 | L29: 入库操作费 | M29: EUR | N29: 72.5 | O29: 0 | P29: 62.5 | Q29: 0 | R29: 62.5 | S29: 个 | T29: 12.5 | U29: 德国法兰克福2仓 | X29: 入库操作费-F230DE-250327（公布价）-3 | AA29: DE | AB29: 65462C | AC29: 65462C | AD29: PZ_国际 | AE29: DEFRAB德国法兰克福2仓 | AK29: Desumidificador AeroDrain D12 | AL29: AeroDrain WiFi除湿机_12L_欧版
A30: IC947270260117143 | B30: SW202601150003DE | C30: FB4 | D30: 入库操作费-DE | E30: 947270 | F30: 2026-03-31 15:23:58 | G30: 0 | H30: 9259.808 | I30: VSK-GIYS448-EU | J30: 18 | K30: 入库操作费 | L30: 入库操作费 | M30: EUR | N30: 55.08 | O30: 0 | P30: 47.34 | Q30: 0 | R30: 47.34 | S30: 个 | T30: 33 | U30: 德国法兰克福2仓 | X30: 入库操作费-F230DE-250327（公布价）-3 | AA30: DE | AB30: 65462C | AC30: 65462C | AD30: PZ_国际 | AE30: DEFRAB德国法兰克福2仓 | AK30: Smart Grow Tent Kit GIY-SE-44 4x4, 4-Plant Complete System | AL30: GIY SGS智能标准款帐篷套装S448欧版
A31: IC947270260117143 | B31: SW202601150003DE | C31: FB4 | D31: 入库操作费-DE | E31: 947270 | F31: 2026-03-31 15:23:58 | G31: 0 | H31: 9259.808 | I31: VSI-VGDWC15-EU | J31: 60 | K31: 入库操作费 | L31: 入库操作费 | M31: EUR | N31: 28.8 | O31: 0 | P31: 24.6 | Q31: 0 | R31: 24.6 | S31: 个 | T31: 5 | U31: 德国法兰克福2仓 | X31: 入库操作费-F230DE-250327（公布价）-3 | AA31: DE | AB31: 65462C | AC31: 65462C | AD31: PZ_国际 | AE31: DEFRAB德国法兰克福2仓 | AK31: VGrow DWC Hydroponics Growing System Kit for VGrow Smart Grow Box | AL31: VGrow DWC水培套装 4加仑
A32: IC947270260117143 | B32: SW202601150003DE | C32: FB4 | D32: 入库操作费-DE | E32: 947270 | F32: 2026-03-31 15:23:58 | G32: 0 | H32: 9259.808 | I32: SST-1-0001-EU | J32: 120 | K32: 入库操作费 | L32: 入库操作费 | M32: EUR | N32: 36 | O32: 0 | P32: 31.2 | Q32: 0 | R32: 31.2 | S32: 个 | T32: 1.13 | U32: 德国法兰克福2仓 | X32: 入库操作费-F230DE-250327（公布价）-3 | AA32: DE | AB32: 65462C | AC32: 65462C | AD32: PZ_国际 | AE32: DEFRAB德国法兰克福2仓 | AK32: 1-Pack 40-Cell Seed Starter Trays with 1 Set of LED Lights and 10"x20.75" Seedling Heat Mat | AL32: 欧规 40孔育苗盘1套装+LED灯条1套+加热垫1套
A33: IC947270260117143 | B33: SW202601150003DE | C33: FB4 | D33: 入库操作费-DE | E33: 947270 | F33: 2026-03-31 15:23:58 | G33: 0 | H33: 9259.808 | I33: E331904J-EU | J33: 30 | K33: 入库操作费 | L33: 入库操作费 | M33: EUR | N33: 28.2 | O33: 0 | P33: 24.3 | Q33: 0 | R33: 24.3 | S33: 个 | T33: 7.25 | U33: 德国法兰克福2仓 | X33: 入库操作费-F230DE-250327（公布价）-3 | AA33: DE | AB33: 65462C | AC33: 65462C | AD33: PZ_国际 | AE33: DEFRAB德国法兰克福2仓 | AK33: E331904J || New lawn mower 19" (with orange flower trimmer) | AL33: E331904J||新款 割草机19"（带橘色花枝剪）
A34: IC947270260117143 | B34: SW202601150003DE | C34: FB4 | D34: 入库操作费-DE | E34: 947270 | F34: 2026-03-31 15:23:58 | G34: 0 | H34: 9259.808 | I34: 304113-P426-EU | J34: 40 | K34: 入库操作费 | L34: 入库操作费 | M34: EUR | N34: 58 | O34: 0 | P34: 50 | Q34: 0 | R34: 50 | S34: 个 | T34: 15 | U34: 德国法兰克福2仓 | X34: 入库操作费-F230DE-250327（公布价）-3 | AA34: DE | AB34: 65462C | AC34: 65462C | AD34: PZ_国际 | AE34: DEFRAB德国法兰克福2仓 | AK34: P426 48"×24"×72" PRO Grow Tent | AL34: P426 Pro款42帐篷-48"x24"x72"/120*60*180cm 22mm管径
A35: IC947270260117143 | B35: SW202601150003DE | C35: FB4 | D35: 入库操作费-DE | E35: 947270 | F35: 2026-03-31 15:23:58 | G35: 0 | H35: 9259.808 | I35: 304113-P448-EU | J35: 20 | K35: 入库操作费 | L35: 入库操作费 | M35: EUR | N35: 38.6 | O35: 0 | P35: 33.2 | Q35: 0 | R35: 33.2 | S35: 个 | T35: 20 | U35: 德国法兰克福2仓 | X35: 入库操作费-F230DE-250327（公布价）-3 | AA35: DE | AB35: 65462C | AC35: 65462C | AD35: PZ_国际 | AE35: DEFRAB德国法兰克福2仓 | AK35: P448 48"×48"×80" PRO Grow Tent | AL35: P448 Pro款44帐篷-48"x48"x80"/120*120*200cm 22mm管径
A36: IC947270260117143 | B36: SW202601150003DE | C36: FB4 | D36: 入库操作费-DE | E36: 947270 | F36: 2026-03-31 15:23:58 | G36: 0 | H36: 9259.808 | I36: VSVC-AZT4E42AP-EU | J36: 45 | K36: 入库操作费 | L36: 入库操作费 | M36: EUR | N36: 42.3 | O36: 0 | P36: 36.45 | Q36: 0 | R36: 36.45 | S36: 个 | T36: 6.5 | U36: 德国法兰克福2仓 | X36: 入库操作费-F230DE-250327（公布价）-3 | AA36: DE | AB36: 65462C | AC36: 65462C | AD36: PZ_国际 | AE36: DEFRAB德国法兰克福2仓 | AK36: Smart Air Filtration PRO T4 Kit 4" | AL36: AeroZesh T4 金属底座风机 4寸 + GrowHub E42A+控制器+黑色滤芯4寸+黑色风管4寸8ft 欧版
A37: IC947270260117143 | B37: SW202601150003DE | C37: FB4 | D37: 入库操作费-DE | E37: 947270 | F37: 2026-03-31 15:23:58 | G37: 0 | H37: 9259.808 | I37: 304113-P558-EU | J37: 12 | K37: 入库操作费 | L37: 入库操作费 | M37: EUR | N37: 28.8 | O37: 0 | P37: 24.72 | Q37: 0 | R37: 24.72 | S37: 个 | T37: 24 | U37: 德国法兰克福2仓 | X37: 入库操作费-F230DE-250327（公布价）-3 | AA37: DE | AB37: 65462C | AC37: 65462C | AD37: PZ_国际 | AE37: DEFRAB德国法兰克福2仓 | AK37: P558 60"×60"×80" PRO Grow Tent | AL37: P558 Pro款55帐篷-60"x60"x80"/150*150*200cm 22mm管径
A38: IC947270260117155 | B38: SW202601150006DE | C38: FB4 | D38: 入库操作费-DE | E38: 947270 | F38: 2026-04-15 20:24:26 | G38: 0 | H38: 8440.56 | I38: VSL-LL100X2-EU,VSV-IFP4C-EU,VSV-IFP6C-EU | J38: 20,160,48 | K38: 入库操作费 | L38: 海外仓查验费 | M38: EUR | N38: 8.25 | O38: 0 | P38: 8.25 | Q38: 0 | R38: 8.25 | U38: 德国法兰克福2仓 | X38: 入库操作费-F230DE_260410（公布价)-2 | AA38: DE | AB38: 65462C | AC38: 65462C | AD38: PZ_国际 | AE38: DEFRAB德国法兰克福2仓 | AG38: 是 | AK38: Lumalight Grow Light 100Wx2,Plastic exhaust fan with adjustable speed 4 inch,Plastic exhaust fan with adjustable speed 6 inch | AL38: VS-lumalight-量子版2025-100W-两只装-EU,P4 塑料抽风扇调速款单品-欧标,P6 塑料抽风扇调速款单品-欧标
A39: IC947270260117155 | B39: SW202601150006DE | C39: FB4 | D39: 入库操作费-DE | E39: 947270 | F39: 2026-04-15 20:24:26 | G39: 0 | H39: 8440.56 | K39: 入库操作费 | L39: 入库卸货费 | M39: EUR | N39: 0 | O39: 0 | P39: 0 | Q39: 0 | R39: 0 | S39: mums.measurement_info.code.CBM | T39: 45.18257 | U39: 德国法兰克福2仓 | X39: 入库操作费-F230DE_260410（公布价)-2 | AA39: DE | AB39: 65462C | AC39: 65462C | AD39: PZ_国际 | AE39: DEFRAB德国法兰克福2仓 | AG39: 是
A40: IC947270260117155 | B40: SW202601150006DE | C40: FB4 | D40: 入库操作费-DE | E40: 947270 | F40: 2026-04-15 20:24:26 | G40: 0 | H40: 8440.56 | I40: 330101CNJ-EU | J40: 120 | K40: 入库操作费 | L40: 入库操作费 | M40: EUR | N40: 33.6 | O40: 0 | P40: 28.8 | Q40: 0 | R40: 28.8 | S40: 个 | T40: 0.85 | U40: 德国法兰克福2仓 | X40: 入库操作费-F230DE_260410（公布价)-2 | AA40: DE | AB40: 65462C | AC40: 65462C | AD40: PZ_国际 | AE40: DEFRAB德国法兰克福2仓 | AG40: 是 | AK40: 10"x 20.75" Seedling Heat Mat and Digital Thermostat Combo Set | AL40: 欧规 恒温器+育苗垫组合10*20
...

Sheet 入库订单 (2)
A1: 业务单号 | B1: 客户单号 | C1: 客户单号 | D1: 平台 | E1: 服务类别 | F1: 服务产品 | G1: 下单子账号 | H1: 计费时间 | I1: 计费重 | J1: 实重 | K1: SKU | L1: SKU数量 | M1: 费用类型 | N1: 费用名称 | O1: 币种 | P1: 计费金额 | Q1: 优惠金额 | R1: 应收金额 | S1: 含代收代付税费 | T1: 可开票金额 | U1: 计费单位 | V1: 计费数量 | W1: 计费地点 | X1: 计算公式 | Y1: 数字公式 | Z1: 报价单编号 | AA1: 优惠券信息 | AB1: 服务商单号 | AC1: 目的地国家 | AD1: 起运地邮编 | AE1: 目的地邮编 | AF1: 起运分区 | AG1: 目的分区 | AH1: 分区名称 | AI1: 有红冲单 | AJ1: 划拨单号 | AK1: 是否跨月重计 | AL1: 备注 | AM1: SKU英文 | AN1: SKU中文 | AO1: 关联入库单号
A2: IC947270260117132 | B2: SW202601150004DE | C2: SW202601150004DE | D2: VS AMZ28.41+WEB39.96 除湿机+空调含制冷剂 | E2: FB4 | F2: 入库操作费-DE | G2: 947270 | H2: 2026-03-31 17:38:38 | I2: 0 | J2: 10762.26 | K2: VSF-AWA6G2X2-EU | L2: 240 | M2: 入库操作费 | N2: 海外仓查验费 | O2: EUR | P2: 2.75 | Q2: 0 | R2: 2.75 | S2: 0 | T2: 2.75 | W2: 德国法兰克福2仓 | Z2: 入库操作费-F230DE-250327（公布价）-3 | AC2: DE | AD2: 65462C | AE2: 65462C | AF2: PZ_国际 | AG2: DEFRAB德国法兰克福2仓 | AM2: 2-Pack AeroWave A6 Gen2 Grow Tent Clip Fan | AN2: 入门款AC电机夹扇A6 Gen2 欧版 两只装
A3: IC947270260117132 | B3: SW202601150004DE | C3: SW202601150004DE | D3: VS AMZ28.41+WEB39.96 除湿机+空调含制冷剂 | E3: FB4 | F3: 入库操作费-DE | G3: 947270 | H3: 2026-03-31 17:38:38 | I3: 0 | J3: 10762.26 | M3: 入库操作费 | N3: 入库卸货费 | O3: EUR | P3: 348.6 | Q3: 0 | R3: 348.6 | S3: 0 | T3: 348.6 | U3: mums.measurement_info.code.CBM | V3: 67.03768 | W3: 德国法兰克福2仓 | Z3: 入库操作费-F230DE-250327（公布价）-3 | AC3: DE | AD3: 65462C | AE3: 65462C | AF3: PZ_国际 | AG3: DEFRAB德国法兰克福2仓
A4: IC947270260117132 | B4: SW202601150004DE | C4: SW202601150004DE | D4: VS AMZ28.41+WEB39.96 除湿机+空调含制冷剂 | E4: FB4 | F4: 入库操作费-DE | G4: 947270 | H4: 2026-03-31 17:38:38 | I4: 0 | J4: 10762.26 | K4: VSE-ALC08-EU | L4: 180 | M4: 入库操作费 | N4: 入库操作费 | O4: EUR | P4: 432 | Q4: 0 | R4: 370.8 | S4: 0 | T4: 370.8 | U4: 个 | V4: 25.778 | W4: 德国法兰克福2仓 | Z4: 入库操作费-F230DE-250327（公布价）-3 | AC4: DE | AD4: 65462C | AE4: 65462C | AF4: PZ_国际 | AG4: DEFRAB德国法兰克福2仓 | AM4: AeroLush Air Conditioner - 8000 BTU - European Standard | AN4: AeroLush 空调_8000BTU_欧规
A5: IC947270260117132 | B5: SW202601150004DE | C5: SW202601150004DE | D5: VS AMZ28.41+WEB39.96 除湿机+空调含制冷剂 | E5: FB4 | F5: 入库操作费-DE | G5: 947270 | H5: 2026-03-31 17:38:38 | I5: 0 | J5: 10762.26 | K5: VSE-ASH05-EU | L5: 240 | M5: 入库操作费 | N5: 入库操作费 | O5: EUR | P5: 72 | Q5: 0 | R5: 62.4 | S5: 0 | T5: 62.4 | U5: 个 | V5: 1.954 | W5: 德国法兰克福2仓 | Z5: 入库操作费-F230DE-250327（公布价）-3 | AC5: DE | AD5: 65462C | AE5: 65462C | AF5: PZ_国际 | AG5: DEFRAB德国法兰克福2仓 | AM5: AeroStream Humidificateur pour plantes 5 l | AN5: AeroStream 5L智能Wi-Fi加湿器（SGS，单核雾化片）-欧版
A6: IC947270260117132 | B6: SW202601150004DE | C6: SW202601150004DE | D6: VS AMZ28.41+WEB39.96 除湿机+空调含制冷剂 | E6: FB4 | F6: 入库操作费-DE | G6: 947270 | H6: 2026-03-31 17:38:38 | I6: 0 | J6: 10762.26 | K6: VSE-ADD12-EU | L6: 240 | M6: 入库操作费 | N6: 入库操作费 | O6: EUR | P6: 348 | Q6: 0 | R6: 300 | S6: 0 | T6: 300 | U6: 个 | V6: 12.5 | W6: 德国法兰克福2仓 | Z6: 入库操作费-F230DE-250327（公布价）-3 | AC6: DE | AD6: 65462C | AE6: 65462C | AF6: PZ_国际 | AG6: DEFRAB德国法兰克福2仓 | AM6: Desumidificador AeroDrain D12 | AN6: AeroDrain WiFi除湿机_12L_欧版
A7: IC947270260117132 | B7: SW202601150004DE | C7: SW202601150004DE | D7: VS AMZ28.41+WEB39.96 除湿机+空调含制冷剂 | E7: FB4 | F7: 入库操作费-DE | G7: 947270 | H7: 2026-03-31 17:38:38 | I7: 0 | J7: 10762.26 | K7: VG-Y18B-EU | L7: 50 | M7: 入库操作费 | N7: 入库操作费 | O7: EUR | P7: 120 | Q7: 0 | R7: 103 | S7: 0 | T7: 103 | U7: 个 | V7: 23.55 | W7: 德国法兰克福2仓 | Z7: 入库操作费-F230DE-250327（公布价）-3 | AC7: DE | AD7: 65462C | AE7: 65462C | AF7: PZ_国际 | AG7: DEFRAB德国法兰克福2仓 | AM7: 欧版 VGrow 智能种植箱 | AN7: 欧版 VGrow 智能种植箱
A8: IC947270260117132 | B8: SW202601150004DE | C8: SW202601150004DE | D8: VS AMZ28.41+WEB39.96 除湿机+空调含制冷剂 | E8: FB4 | F8: 入库操作费-DE | G8: 947270 | H8: 2026-03-31 17:38:38 | I8: 0 | J8: 10762.26 | K8: 306146-0412-EU | L8: 300 | M8: 入库操作费 | N8: 入库操作费 | O8: EUR | P8: 90 | Q8: 0 | R8: 78 | S8: 0 | T8: 78 | U8: 个 | V8: 2.826 | W8: 德国法兰克福2仓 | Z8: 入库操作费-F230DE-250327（公布价）-3 | AC8: DE | AD8: 65462C | AE8: 65462C | AF8: PZ_国际 | AG8: DEFRAB德国法兰克福2仓 | AM8: VIVOSUN钢印滤芯 黑色4" | AN8: VIVOSUN钢印滤芯 黑色4"
A9: IC947270260117132 | B9: SW202601150004DE | C9: SW202601150004DE | D9: VS AMZ28.41+WEB39.96 除湿机+空调含制冷剂 | E9: FB4 | F9: 入库操作费-DE | G9: 947270 | H9: 2026-03-31 17:38:38 | I9: 0 | J9: 10762.26 | K9: VSF-AWA6G2X2-EU | L9: 240 | M9: 入库操作费 | N9: 入库操作费 | O9: EUR | P9: 72 | Q9: 0 | R9: 62.4 | S9: 0 | T9: 62.4 | U9: 个 | V9: 2.838 | W9: 德国法兰克福2仓 | Z9: 入库操作费-F230DE-250327（公布价）-3 | AC9: DE | AD9: 65462C | AE9: 65462C | AF9: PZ_国际 | AG9: DEFRAB德国法兰克福2仓 | AM9: 2-Pack AeroWave A6 Gen2 Grow Tent Clip Fan | AN9: 入门款AC电机夹扇A6 Gen2 欧版 两只装
A10: IC947270260117143 | B10: SW202601150003DE | C10: SW202601150003DE | D10: VS Amazon25.39+eBay4.78+Web38.15 除湿机含制冷剂 | E10: FB4 | F10: 入库操作费-DE | G10: 947270 | H10: 2026-03-31 15:23:58 | I10: 0 | J10: 9259.808 | K10: VSF-AWA6G2-EU | L10: 240 | M10: 入库操作费 | N10: 海外仓查验费 | O10: EUR | P10: 2.75 | Q10: 0 | R10: 2.75 | S10: 0 | T10: 2.75 | W10: 德国法兰克福2仓 | Z10: 入库操作费-F230DE-250327（公布价）-3 | AC10: DE | AD10: 65462C | AE10: 65462C | AF10: PZ_国际 | AG10: DEFRAB德国法兰克福2仓 | AM10: Aerowave A6 Gen2 Grow Tent Clip Fan | AN10: 入门款AC电机夹扇A6 Gen2 欧版
A11: IC947270260117143 | B11: SW202601150003DE | C11: SW202601150003DE | D11: VS Amazon25.39+eBay4.78+Web38.15 除湿机含制冷剂 | E11: FB4 | F11: 入库操作费-DE | G11: 947270 | H11: 2026-03-31 15:23:58 | I11: 0 | J11: 9259.808 | M11: 入库操作费 | N11: 入库卸货费 | O11: EUR | P11: 317.89 | Q11: 0 | R11: 317.89 | S11: 0 | T11: 317.89 | U11: mums.measurement_info.code.CBM | V11: 61.13187 | W11: 德国法兰克福2仓 | Z11: 入库操作费-F230DE-250327（公布价）-3 | AC11: DE | AD11: 65462C | AE11: 65462C | AF11: PZ_国际 | AG11: DEFRAB德国法兰克福2仓
A12: IC947270260117143 | B12: SW202601150003DE | C12: SW202601150003DE | D12: VS Amazon25.39+eBay4.78+Web38.15 除湿机含制冷剂 | E12: FB4 | F12: 入库操作费-DE | G12: 947270 | H12: 2026-03-31 15:23:58 | I12: 0 | J12: 9259.808 | K12: VSL-LRUC100-EU | L12: 96 | M12: 入库操作费 | N12: 入库操作费 | O12: EUR | P12: 28.8 | Q12: 0 | R12: 24.96 | S12: 0 | T12: 24.96 | U12: 个 | V12: 2.9 | W12: 德国法兰克福2仓 | Z12: 入库操作费-F230DE-250327（公布价）-3 | AC12: DE | AD12: 65462C | AE12: 65462C | AF12: PZ_国际 | AG12: DEFRAB德国法兰克福2仓 | AM12: Supplemental light LumaRay-under canopy 100W-EU | AN12: Supplemental light LumaRay-under canopy 100W-EU
A13: IC947270260117143 | B13: SW202601150003DE | C13: SW202601150003DE | D13: VS Amazon25.39+eBay4.78+Web38.15 除湿机含制冷剂 | E13: FB4 | F13: 入库操作费-DE | G13: 947270 | H13: 2026-03-31 15:23:58 | I13: 0 | J13: 9259.808 | K13: VG-Y18B-EU | L13: 25 | M13: 入库操作费 | N13: 入库操作费 | O13: EUR | P13: 60 | Q13: 0 | R13: 51.5 | S13: 0 | T13: 51.5 | U13: 个 | V13: 23.55 | W13: 德国法兰克福2仓 | Z13: 入库操作费-F230DE-250327（公布价）-3 | AC13: DE | AD13: 65462C | AE13: 65462C | AF13: PZ_国际 | AG13: DEFRAB德国法兰克福2仓 | AM13: 欧版 VGrow 智能种植箱 | AN13: 欧版 VGrow 智能种植箱
A14: IC947270260117143 | B14: SW202601150003DE | C14: SW202601150003DE | D14: VS Amazon25.39+eBay4.78+Web38.15 除湿机含制冷剂 | E14: FB4 | F14: 入库操作费-DE | G14: 947270 | H14: 2026-03-31 15:23:58 | I14: 0 | J14: 9259.808 | K14: VSVC-AZT6E42AP-EU | L14: 25 | M14: 入库操作费 | N14: 入库操作费 | O14: EUR | P14: 23.5 | Q14: 0 | R14: 20.25 | S14: 0 | T14: 20.25 | U14: 个 | V14: 10 | W14: 德国法兰克福2仓 | Z14: 入库操作费-F230DE-250327（公布价）-3 | AC14: DE | AD14: 65462C | AE14: 65462C | AF14: PZ_国际 | AG14: DEFRAB德国法兰克福2仓 | AM14: Smart Air Filtration Kit Pro 6″ | AN14: AeroZesh T6 金属底座风机 6寸 + GrowHub E42A+控制器+黑色滤芯6寸+黑色风管6寸8ft 欧版
A15: IC947270260117143 | B15: SW202601150003DE | C15: SW202601150003DE | D15: VS Amazon25.39+eBay4.78+Web38.15 除湿机含制冷剂 | E15: FB4 | F15: 入库操作费-DE | G15: 947270 | H15: 2026-03-31 15:23:58 | I15: 0 | J15: 9259.808 | K15: VSF-AWD4X2-EU | L15: 432 | M15: 入库操作费 | N15: 入库操作费 | O15: EUR | P15: 116.64 | Q15: 0 | R15: 99.36 | S15: 0 | T15: 99.36 | U15: 个 | V15: 0.61 | W15: 德国法兰克福2仓 | Z15: 入库操作费-F230DE-250327（公布价）-3 | AC15: DE | AD15: 65462C | AE15: 65462C | AF15: PZ_国际 | AG15: DEFRAB德国法兰克福2仓 | AM15: AeroWave D4, 4” Grow Tent Clip Fan with Detachable Hook
A16: IC947270260117143 | B16: SW202601150003DE | C16: SW202601150003DE | D16: VS Amazon25.39+eBay4.78+Web38.15 除湿机含制冷剂 | E16: FB4 | F16: 入库操作费-DE | G16: 947270 | H16: 2026-03-31 15:23:58 | I16: 0 | J16: 9259.808 | K16: VSE-ATW70-EU | L16: 72 | M16: 入库操作费 | N16: 入库操作费 | O16: EUR | P16: 34.56 | Q16: 0 | R16: 29.52 | S16: 0 | T16: 29.52 | U16: 个 | V16: 3.216 | W16: 德国法兰克福2仓 | Z16: 入库操作费-F230DE-250327（公布价）-3 | AC16: DE | AD16: 65462C | AE16: 65462C | AF16: PZ_国际 | AG16: DEFRAB德国法兰克福2仓 | AM16: AeroFlux Heater 70w | AN16: AeroFlux Heater 70w
A17: IC947270260117143 | B17: SW202601150003DE | C17: SW202601150003DE | D17: VS Amazon25.39+eBay4.78+Web38.15 除湿机含制冷剂 | E17: FB4 | F17: 入库操作费-DE | G17: 947270 | H17: 2026-03-31 15:23:58 | I17: 0 | J17: 9259.808 | K17: VSF-AWA6G2-EU | L17: 240 | M17: 入库操作费 | N17: 入库操作费 | O17: EUR | P17: 72 | Q17: 0 | R17: 62.4 | S17: 0 | T17: 62.4 | U17: 个 | V17: 1.468 | W17: 德国法兰克福2仓 | Z17: 入库操作费-F230DE-250327（公布价）-3 | AC17: DE | AD17: 65462C | AE17: 65462C | AF17: PZ_国际 | AG17: DEFRAB德国法兰克福2仓 | AM17: Aerowave A6 Gen2 Grow Tent Clip Fan | AN17: 入门款AC电机夹扇A6 Gen2 欧版
A18: IC947270260117143 | B18: SW202601150003DE | C18: SW202601150003DE | D18: VS Amazon25.39+eBay4.78+Web38.15 除湿机含制冷剂 | E18: FB4 | F18: 入库操作费-DE | G18: 947270 | H18: 2026-03-31 15:23:58 | I18: 0 | J18: 9259.808 | K18: VSVC-AZG4E42AP-EU | L18: 36 | M18: 入库操作费 | N18: 入库操作费 | O18: EUR | P18: 33.84 | Q18: 0 | R18: 29.16 | S18: 0 | T18: 29.16 | U18: 个 | V18: 7 | W18: 德国法兰克福2仓 | Z18: 入库操作费-F230DE-250327（公布价）-3 | AC18: DE | AD18: 65462C | AE18: 65462C | AF18: PZ_国际 | AG18: DEFRAB德国法兰克福2仓 | AM18: Smart Air Filtration PRO G4 Kit 4" | AN18: AeroZesh G4 金属底座风机 4寸 + GrowHub E42A+控制器+黑色滤芯4寸+黑色风管4寸8ft 欧版
A19: IC947270260117143 | B19: SW202601150003DE | C19: SW202601150003DE | D19: VS Amazon25.39+eBay4.78+Web38.15 除湿机含制冷剂 | E19: FB4 | F19: 入库操作费-DE | G19: 947270 | H19: 2026-03-31 15:23:58 | I19: 0 | J19: 9259.808 | K19: VSF-AWE6-G2-EU | L19: 336 | M19: 入库操作费 | N19: 入库操作费 | O19: EUR | P19: 100.8 | Q19: 0 | R19: 87.36 | S19: 0 | T19: 87.36 | U19: 个 | V19: 1.1 | W19: 德国法兰克福2仓 | Z19: 入库操作费-F230DE-250327（公布价）-3 | AC19: DE | AD19: 65462C | AE19: 65462C | AF19: PZ_国际 | AG19: DEFRAB德国法兰克福2仓 | AM19: AeroWave E6 Grow Tent Fan 6”
A20: IC947270260117143 | B20: SW202601150003DE | C20: SW202601150003DE | D20: VS Amazon25.39+eBay4.78+Web38.15 除湿机含制冷剂 | E20: FB4 | F20: 入库操作费-DE | G20: 947270 | H20: 2026-03-31 15:23:58 | I20: 0 | J20: 9259.808 | K20: 304113-52-EU | L20: 32 | M20: 入库操作费 | N20: 入库操作费 | O20: EUR | P20: 46.4 | Q20: 0 | R20: 40 | S20: 0 | T20: 40 | U20: 个 | V20: 11.821 | W20: 德国法兰克福2仓 | Z20: 入库操作费-F230DE-250327（公布价）-3 | AC20: DE | AD20: 65462C | AE20: 65462C | AF20: PZ_国际 | AG20: DEFRAB德国法兰克福2仓 | AM20: 52帐篷-60"x32"x80"/150*80*200cm 16mm管径 | AN20: 52帐篷-60"x32"x80"/150*80*200cm 16mm管径
A21: IC947270260117143 | B21: SW202601150003DE | C21: SW202601150003DE | D21: VS Amazon25.39+eBay4.78+Web38.15 除湿机含制冷剂 | E21: FB4 | F21: 入库操作费-DE | G21: 947270 | H21: 2026-03-31 15:23:58 | I21: 0 | J21: 9259.808 | K21: E331903J-EU | L21: 36 | M21: 入库操作费 | N21: 入库操作费 | O21: EUR | P21: 33.84 | Q21: 0 | R21: 29.16 | S21: 0 | T21: 29.16 | U21: 个 | V21: 6.262 | W21: 德国法兰克福2仓 | Z21: 入库操作费-F230DE-250327（公布价）-3 | AC21: DE | AD21: 65462C | AE21: 65462C | AF21: PZ_国际 | AG21: DEFRAB德国法兰克福2仓 | AM21: E331903J || New lawn mower 16" (with orange flower trimmer) | AN21: E331903J||新款 割草机16"（带橘色花枝剪）
A22: IC947270260117143 | B22: SW202601150003DE | C22: SW202601150003DE | D22: VS Amazon25.39+eBay4.78+Web38.15 除湿机含制冷剂 | E22: FB4 | F22: 入库操作费-DE | G22: 947270 | H22: 2026-03-31 15:23:58 | I22: 0 | J22: 9259.808 | K22: VSK-GIYS336-EU | L22: 20 | M22: 入库操作费 | N22: 入库操作费 | O22: EUR | P22: 48 | Q22: 0 | R22: 41.2 | S22: 0 | T22: 41.2 | U22: 个 | V22: 23 | W22: 德国法兰克福2仓 | Z22: 入库操作费-F230DE-250327（公布价）-3 | AC22: DE | AD22: 65462C | AE22: 65462C | AF22: PZ_国际 | AG22: DEFRAB德国法兰克福2仓 | AM22: Smart Grow Tent Kit GIY-SE-33 3x3, 3-Plant Complete System | AN22: GIY SGS智能标准款帐篷套装S336欧版
A23: IC947270260117143 | B23: SW202601150003DE | C23: SW202601150003DE | D23: VS Amazon25.39+eBay4.78+Web38.15 除湿机含制冷剂 | E23: FB4 | F23: 入库操作费-DE | G23: 947270 | H23: 2026-03-31 15:23:58 | I23: 0 | J23: 9259.808 | K23: VSE-ASH05-EU | L23: 120 | M23: 入库操作费 | N23: 入库操作费 | O23: EUR | P23: 36 | Q23: 0 | R23: 31.2 | S23: 0 | T23: 31.2 | U23: 个 | V23: 1.954 | W23: 德国法兰克福2仓 | Z23: 入库操作费-F230DE-250327（公布价）-3 | AC23: DE | AD23: 65462C | AE23: 65462C | AF23: PZ_国际 | AG23: DEFRAB德国法兰克福2仓 | AM23: AeroStream Humidificateur pour plantes 5 l | AN23: AeroStream 5L智能Wi-Fi加湿器（SGS，单核雾化片）-欧版
A24: IC947270260117143 | B24: SW202601150003DE | C24: SW202601150003DE | D24: VS Amazon25.39+eBay4.78+Web38.15 除湿机含制冷剂 | E24: FB4 | F24: 入库操作费-DE | G24: 947270 | H24: 2026-03-31 15:23:58 | I24: 0 | J24: 9259.808 | K24: VSE-ASH09-EU | L24: 168 | M24: 入库操作费 | N24: 入库操作费 | O24: EUR | P24: 80.64 | Q24: 0 | R24: 68.88 | S24: 0 | T24: 68.88 | U24: 个 | V24: 3.346 | W24: 德国法兰克福2仓 | Z24: 入库操作费-F230DE-250327（公布价）-3 | AC24: DE | AD24: 65462C | AE24: 65462C | AF24: PZ_国际 | AG24: DEFRAB德国法兰克福2仓 | AM24: AeroStream - Humidificador para plantas (9 L) | AN24: AeroStream 9L智能Wi-Fi加湿器（SGS，单核雾化片）-欧版
A25: IC947270260117143 | B25: SW202601150003DE | C25: SW202601150003DE | D25: VS Amazon25.39+eBay4.78+Web38.15 除湿机含制冷剂 | E25: FB4 | F25: 入库操作费-DE | G25: 947270 | H25: 2026-03-31 15:23:58 | I25: 0 | J25: 9259.808 | K25: VSI-FFSW6-4-EU | L25: 120 | M25: 入库操作费 | N25: 入库操作费 | O25: EUR | P25: 57.6 | Q25: 0 | R25: 49.2 | S25: 0 | T25: 49.2 | U25: 个 | V25: 4.72 | W25: 德国法兰克福2仓 | Z25: 入库操作费-F230DE-250327（公布价）-3 | AC25: DE | AD25: 65462C | AE25: 65462C | AF25: PZ_国际 | AG25: DEFRAB德国法兰克福2仓 | AM25: 4-Pack FlexFeed Self-Watering Irrigation Pot
A26: IC947270260117143 | B26: SW202601150003DE | C26: SW202601150003DE | D26: VS Amazon25.39+eBay4.78+Web38.15 除湿机含制冷剂 | E26: FB4 | F26: 入库操作费-DE | G26: 947270 | H26: 2026-03-31 15:23:58 | I26: 0 | J26: 9259.808 | K26: VST-SP2-GL-EU | L26: 200 | M26: 入库操作费 | N26: 入库操作费 | O26: EUR | P26: 60 | Q26: 0 | R26: 52 | S26: 0 | T26: 52 | U26: 个 | V26: 2.014 | W26: 德国法兰克福2仓 | Z26: 入库操作费-F230DE-250327（公布价）-3 | AC26: DE | AD26: 65462C | AE26: 65462C | AF26: PZ_国际 | AG26: DEFRAB德国法兰克福2仓 | AM26: Grow Tent High CFM Kit 100-150cm | AN26: 帐篷伸缩支撑杆100-150cm
A27: IC947270260117143 | B27: SW202601150003DE | C27: SW202601150003DE | D27: VS Amazon25.39+eBay4.78+Web38.15 除湿机含制冷剂 | E27: FB4 | F27: 入库操作费-DE | G27: 947270 | H27: 2026-03-31 15:23:58 | I27: 0 | J27: 9259.808 | K27: VSFL6450-EU | L27: 15 | M27: 入库操作费 | N27: 入库操作费 | O27: EUR | P27: 14.1 | Q27: 0 | R27: 12.15 | S27: 0 | T27: 12.15 | U27: 个 | V27: 10 | W27: 德国法兰克福2仓 | Z27: 入库操作费-F230DE-250327（公布价）-3 | AC27: DE | AD27: 65462C | AE27: 65462C | AF27: PZ_国际 | AG27: DEFRAB德国法兰克福2仓 | AM27: LED Grow Light
A28: IC947270260117143 | B28: SW202601150003DE | C28: SW202601150003DE | D28: VS Amazon25.39+eBay4.78+Web38.15 除湿机含制冷剂 | E28: FB4 | F28: 入库操作费-DE | G28: 947270 | H28: 2026-03-31 15:23:58 | I28: 0 | J28: 9259.808 | K28: VSEX-HID1-ST-EU | L28: 88 | M28: 入库操作费 | N28: 入库操作费 | O28: EUR | P28: 42.24 | Q28: 0 | R28: 36.08 | S28: 0 | T28: 36.08 | U28: 个 | V28: 3.812 | W28: 德国法兰克福2仓 | Z28: 入库操作费-F230DE-250327（公布价）-3 | AC28: DE | AD28: 65462C | AE28: 65462C | AF28: PZ_国际 | AG28: DEFRAB德国法兰克福2仓 | AM28: Herbal Decarboxylation and Infusion Machine | AN28: S4508B 黄油机套装-欧版
A29: IC947270260117143 | B29: SW202601150003DE | C29: SW202601150003DE | D29: VS Amazon25.39+eBay4.78+Web38.15 除湿机含制冷剂 | E29: FB4 | F29: 入库操作费-DE | G29: 947270 | H29: 2026-03-31 15:23:58 | I29: 0 | J29: 9259.808 | K29: VSE-ADD12-EU | L29: 50 | M29: 入库操作费 | N29: 入库操作费 | O29: EUR | P29: 72.5 | Q29: 0 | R29: 62.5 | S29: 0 | T29: 62.5 | U29: 个 | V29: 12.5 | W29: 德国法兰克福2仓 | Z29: 入库操作费-F230DE-250327（公布价）-3 | AC29: DE | AD29: 65462C | AE29: 65462C | AF29: PZ_国际 | AG29: DEFRAB德国法兰克福2仓 | AM29: Desumidificador AeroDrain D12 | AN29: AeroDrain WiFi除湿机_12L_欧版
A30: IC947270260117143 | B30: SW202601150003DE | C30: SW202601150003DE | D30: VS Amazon25.39+eBay4.78+Web38.15 除湿机含制冷剂 | E30: FB4 | F30: 入库操作费-DE | G30: 947270 | H30: 2026-03-31 15:23:58 | I30: 0 | J30: 9259.808 | K30: VSK-GIYS448-EU | L30: 18 | M30: 入库操作费 | N30: 入库操作费 | O30: EUR | P30: 55.08 | Q30: 0 | R30: 47.34 | S30: 0 | T30: 47.34 | U30: 个 | V30: 33 | W30: 德国法兰克福2仓 | Z30: 入库操作费-F230DE-250327（公布价）-3 | AC30: DE | AD30: 65462C | AE30: 65462C | AF30: PZ_国际 | AG30: DEFRAB德国法兰克福2仓 | AM30: Smart Grow Tent Kit GIY-SE-44 4x4, 4-Plant Complete System | AN30: GIY SGS智能标准款帐篷套装S448欧版
A31: IC947270260117143 | B31: SW202601150003DE | C31: SW202601150003DE | D31: VS Amazon25.39+eBay4.78+Web38.15 除湿机含制冷剂 | E31: FB4 | F31: 入库操作费-DE | G31: 947270 | H31: 2026-03-31 15:23:58 | I31: 0 | J31: 9259.808 | K31: VSI-VGDWC15-EU | L31: 60 | M31: 入库操作费 | N31: 入库操作费 | O31: EUR | P31: 28.8 | Q31: 0 | R31: 24.6 | S31: 0 | T31: 24.6 | U31: 个 | V31: 5 | W31: 德国法兰克福2仓 | Z31: 入库操作费-F230DE-250327（公布价）-3 | AC31: DE | AD31: 65462C | AE31: 65462C | AF31: PZ_国际 | AG31: DEFRAB德国法兰克福2仓 | AM31: VGrow DWC Hydroponics Growing System Kit for VGrow Smart Grow Box | AN31: VGrow DWC水培套装 4加仑
A32: IC947270260117143 | B32: SW202601150003DE | C32: SW202601150003DE | D32: VS Amazon25.39+eBay4.78+Web38.15 除湿机含制冷剂 | E32: FB4 | F32: 入库操作费-DE | G32: 947270 | H32: 2026-03-31 15:23:58 | I32: 0 | J32: 9259.808 | K32: SST-1-0001-EU | L32: 120 | M32: 入库操作费 | N32: 入库操作费 | O32: EUR | P32: 36 | Q32: 0 | R32: 31.2 | S32: 0 | T32: 31.2 | U32: 个 | V32: 1.13 | W32: 德国法兰克福2仓 | Z32: 入库操作费-F230DE-250327（公布价）-3 | AC32: DE | AD32: 65462C | AE32: 65462C | AF32: PZ_国际 | AG32: DEFRAB德国法兰克福2仓 | AM32: 1-Pack 40-Cell Seed Starter Trays with 1 Set of LED Lights and 10"x20.75" Seedling Heat Mat | AN32: 欧规 40孔育苗盘1套装+LED灯条1套+加热垫1套
A33: IC947270260117143 | B33: SW202601150003DE | C33: SW202601150003DE | D33: VS Amazon25.39+eBay4.78+Web38.15 除湿机含制冷剂 | E33: FB4 | F33: 入库操作费-DE | G33: 947270 | H33: 2026-03-31 15:23:58 | I33: 0 | J33: 9259.808 | K33: E331904J-EU | L33: 30 | M33: 入库操作费 | N33: 入库操作费 | O33: EUR | P33: 28.2 | Q33: 0 | R33: 24.3 | S33: 0 | T33: 24.3 | U33: 个 | V33: 7.25 | W33: 德国法兰克福2仓 | Z33: 入库操作费-F230DE-250327（公布价）-3 | AC33: DE | AD33: 65462C | AE33: 65462C | AF33: PZ_国际 | AG33: DEFRAB德国法兰克福2仓 | AM33: E331904J || New lawn mower 19" (with orange flower trimmer) | AN33: E331904J||新款 割草机19"（带橘色花枝剪）
A34: IC947270260117143 | B34: SW202601150003DE | C34: SW202601150003DE | D34: VS Amazon25.39+eBay4.78+Web38.15 除湿机含制冷剂 | E34: FB4 | F34: 入库操作费-DE | G34: 947270 | H34: 2026-03-31 15:23:58 | I34: 0 | J34: 9259.808 | K34: 304113-P426-EU | L34: 40 | M34: 入库操作费 | N34: 入库操作费 | O34: EUR | P34: 58 | Q34: 0 | R34: 50 | S34: 0 | T34: 50 | U34: 个 | V34: 15 | W34: 德国法兰克福2仓 | Z34: 入库操作费-F230DE-250327（公布价）-3 | AC34: DE | AD34: 65462C | AE34: 65462C | AF34: PZ_国际 | AG34: DEFRAB德国法兰克福2仓 | AM34: P426 48"×24"×72" PRO Grow Tent | AN34: P426 Pro款42帐篷-48"x24"x72"/120*60*180cm 22mm管径
A35: IC947270260117143 | B35: SW202601150003DE | C35: SW202601150003DE | D35: VS Amazon25.39+eBay4.78+Web38.15 除湿机含制冷剂 | E35: FB4 | F35: 入库操作费-DE | G35: 947270 | H35: 2026-03-31 15:23:58 | I35: 0 | J35: 9259.808 | K35: 304113-P448-EU | L35: 20 | M35: 入库操作费 | N35: 入库操作费 | O35: EUR | P35: 38.6 | Q35: 0 | R35: 33.2 | S35: 0 | T35: 33.2 | U35: 个 | V35: 20 | W35: 德国法兰克福2仓 | Z35: 入库操作费-F230DE-250327（公布价）-3 | AC35: DE | AD35: 65462C | AE35: 65462C | AF35: PZ_国际 | AG35: DEFRAB德国法兰克福2仓 | AM35: P448 48"×48"×80" PRO Grow Tent | AN35: P448 Pro款44帐篷-48"x48"x80"/120*120*200cm 22mm管径
A36: IC947270260117143 | B36: SW202601150003DE | C36: SW202601150003DE | D36: VS Amazon25.39+eBay4.78+Web38.15 除湿机含制冷剂 | E36: FB4 | F36: 入库操作费-DE | G36: 947270 | H36: 2026-03-31 15:23:58 | I36: 0 | J36: 9259.808 | K36: VSVC-AZT4E42AP-EU | L36: 45 | M36: 入库操作费 | N36: 入库操作费 | O36: EUR | P36: 42.3 | Q36: 0 | R36: 36.45 | S36: 0 | T36: 36.45 | U36: 个 | V36: 6.5 | W36: 德国法兰克福2仓 | Z36: 入库操作费-F230DE-250327（公布价）-3 | AC36: DE | AD36: 65462C | AE36: 65462C | AF36: PZ_国际 | AG36: DEFRAB德国法兰克福2仓 | AM36: Smart Air Filtration PRO T4 Kit 4" | AN36: AeroZesh T4 金属底座风机 4寸 + GrowHub E42A+控制器+黑色滤芯4寸+黑色风管4寸8ft 欧版
A37: IC947270260117143 | B37: SW202601150003DE | C37: SW202601150003DE | D37: VS Amazon25.39+eBay4.78+Web38.15 除湿机含制冷剂 | E37: FB4 | F37: 入库操作费-DE | G37: 947270 | H37: 2026-03-31 15:23:58 | I37: 0 | J37: 9259.808 | K37: 304113-P558-EU | L37: 12 | M37: 入库操作费 | N37: 入库操作费 | O37: EUR | P37: 28.8 | Q37: 0 | R37: 24.72 | S37: 0 | T37: 24.72 | U37: 个 | V37: 24 | W37: 德国法兰克福2仓 | Z37: 入库操作费-F230DE-250327（公布价）-3 | AC37: DE | AD37: 65462C | AE37: 65462C | AF37: PZ_国际 | AG37: DEFRAB德国法兰克福2仓 | AM37: P558 60"×60"×80" PRO Grow Tent | AN37: P558 Pro款55帐篷-60"x60"x80"/150*150*200cm 22mm管径
A38: IC947270260117155 | B38: SW202601150006DE | C38: SW202601150006DE | D38: VS Amazon+eBay+Web 58.5方 11354KG 1519箱 测试笔+喷雾器+滴灌套装 含电 除湿机含制冷剂 | E38: FB4 | F38: 入库操作费-DE | G38: 947270 | H38: 2026-04-15 20:24:26 | I38: 0 | J38: 8440.56 | K38: VSL-LL100X2-EU,VSV-IFP4C-EU,VSV-IFP6C-EU | L38: 20,160,48 | M38: 入库操作费 | N38: 海外仓查验费 | O38: EUR | P38: 8.25 | Q38: 0 | R38: 8.25 | S38: 0 | T38: 8.25 | W38: 德国法兰克福2仓 | Z38: 入库操作费-F230DE_260410（公布价)-2 | AC38: DE | AD38: 65462C | AE38: 65462C | AF38: PZ_国际 | AG38: DEFRAB德国法兰克福2仓 | AI38: 是 | AM38: Lumalight Grow Light 100Wx2,Plastic exhaust fan with adjustable speed 4 inch,Plastic exhaust fan with adjustable speed 6 inch | AN38: VS-lumalight-量子版2025-100W-两只装-EU,P4 塑料抽风扇调速款单品-欧标,P6 塑料抽风扇调速款单品-欧标
A39: IC947270260117155 | B39: SW202601150006DE | C39: SW202601150006DE | D39: VS Amazon+eBay+Web 58.5方 11354KG 1519箱 测试笔+喷雾器+滴灌套装 含电 除湿机含制冷剂 | E39: FB4 | F39: 入库操作费-DE | G39: 947270 | H39: 2026-04-15 20:24:26 | I39: 0 | J39: 8440.56 | K39: 330101CNJ-EU | L39: 120 | M39: 入库操作费 | N39: 入库操作费 | O39: EUR | P39: 33.6 | Q39: 0 | R39: 28.8 | S39: 0 | T39: 28.8 | U39: 个 | V39: 0.85 | W39: 德国法兰克福2仓 | Z39: 入库操作费-F230DE_260410（公布价)-2 | AC39: DE | AD39: 65462C | AE39: 65462C | AF39: PZ_国际 | AG39: DEFRAB德国法兰克福2仓 | AI39: 是 | AM39: 10"x 20.75" Seedling Heat Mat and Digital Thermostat Combo Set | AN39: 欧规 恒温器+育苗垫组合10*20
A40: IC947270260117155 | B40: SW202601150006DE | C40: SW202601150006DE | D40: VS Amazon+eBay+Web 58.5方 11354KG 1519箱 测试笔+喷雾器+滴灌套装 含电 除湿机含制冷剂 | E40: FB4 | F40: 入库操作费-DE | G40: 947270 | H40: 2026-04-15 20:24:26 | I40: 0 | J40: 8440.56 | K40: VSL-LRUC100-EU | L40: 92 | M40: 入库操作费 | N40: 入库操作费 | O40: EUR | P40: 30.36 | Q40: 0 | R40: 25.76 | S40: 0 | T40: 25.76 | U40: 个 | V40: 2.9 | W40: 德国法兰克福2仓 | Z40: 入库操作费-F230DE_260410（公布价)-2 | AC40: DE | AD40: 65462C | AE40: 65462C | AF40: PZ_国际 | AG40: DEFRAB德国法兰克福2仓 | AI40: 是 | AM40: Supplemental light LumaRay-under canopy 100W-EU | AN40: Supplemental light LumaRay-under canopy 100W-EU
...

Sheet 出库订单
A1: 出库时间 | B1: 业务单号 | C1: 客户单号 | D1: 下单子账号 | E1: SKU | F1: SKU数量 | G1: 服务类别 | H1: 服务产品 | I1: 计费时间 | J1: 计费重 | K1: 实重 | L1: 费用类型 | M1: 费用名称 | N1: 库龄 | O1: 币种 | P1: 计费金额 | Q1: 优惠金额 | R1: 应收金额 | S1: 含代收代付税费 | T1: 可开票金额 | U1: 计算公式 | V1: 数字公式 | W1: 产品类型 | X1: 计费单位 | Y1: 计费数量 | Z1: 计费地点 | AA1: 报价单编号 | AB1: 优惠券信息 | AC1: 服务商单号 | AD1: 目的地国家 | AE1: 起运地邮编 | AF1: 目的地邮编 | AG1: 起运分区 | AH1: 目的分区 | AI1: 分区名称 | AJ1: 业务单状态 | AK1: 有红冲单 | AL1: 划拨单号 | AM1: 是否跨月重计 | AN1: 备注 | AO1: SKU英文 | AP1: SKU中文
B2: 606761975658 | C2: 05-14373-05460 | D2: 947270 | E2: 304113-52-EU | F2: 1 | G2: FB4 | H2: DE_DHL_RETURN_L | I2: 2026-03-19 11:25:53 | J2: 0 | K2: 11.821 | L2: FB4尾程 | M2: 超长超重附加费 | N2: 0 | O2: EUR | P2: 14 | Q2: 0 | R2: 14 | S2: 0 | T2: 14 | X2: 千克 | Y2: 0 | Z2: 德国法兰克福2仓 | AC2: 00340434648320258819 | AD2: DE | AE2: 71726 | AF2: 55459 | AM2: 是 | AN2: 【杂费加收备注:超长超重附加费】 | AO2: 52帐篷-60"x32"x80"/150*80*200cm 16mm管径 | AP2: 52帐篷-60"x32"x80"/150*80*200cm 16mm管径
B3: 606783542625 | C3: 09-14388-03807 | D3: 947270 | E3: 304114-43TENTKIT-EU | F3: 1 | G3: FB4 | H3: DE_DHL_RETURN_L | I3: 2026-03-31 13:45:56 | J3: 0 | K3: 31.5 | L3: FB4尾程 | M3: 超长超重附加费 | N3: 0 | O3: EUR | P3: 14 | Q3: 0 | R3: 14 | S3: 0 | T3: 14 | X3: 千克 | Y3: 0 | Z3: 德国法兰克福2仓 | AC3: 00340434648320290680 | AD3: DE | AE3: 37154 | AF3: 55459 | AM3: 是 | AN3: 【杂费加收备注:超长超重附加费】 | AO3: 2-in-1 Grow Tent Kit | AP3: 2合一 帐篷 套装
B4: 606785493240 | C4: 167739312226332841-1 | D4: 947270 | E4: VSE-ADD12-EU | F4: 1 | G4: FB4 | H4: DE_DHL_RETURN_L | I4: 2026-04-01 14:50:27 | J4: 12.5 | K4: 12.5 | L4: FB4尾程 | M4: 高速公路费 | N4: 0 | O4: EUR | P4: 0.19 | Q4: 0 | R4: 0.19 | S4: 0 | T4: 0.19 | X4: 千克 | Y4: 12.5 | Z4: 德国法兰克福2仓 | AA4: PQ_F1127_20260101 | AC4: 00340434648320294268 | AD4: DE | AE4: 99974 | AF4: 55459 | AO4: Desumidificador AeroDrain D12 | AP4: AeroDrain WiFi除湿机_12L_欧版
B5: 606785493240 | C5: 167739312226332841-1 | D5: 947270 | E5: VSE-ADD12-EU | F5: 1 | G5: FB4 | H5: DE_DHL_RETURN_L | I5: 2026-04-01 14:50:27 | J5: 12.5 | K5: 12.5 | L5: FB4尾程 | M5: 回邮运费 | N5: 0 | O5: EUR | P5: 4.11 | Q5: 0 | R5: 3.37 | S5: 0 | T5: 3.37 | X5: 千克 | Y5: 12.5 | Z5: 德国法兰克福2仓 | AA5: PQ_F1127_20260101 | AC5: 00340434648320294268 | AD5: DE | AE5: 99974 | AF5: 55459 | AG5: PZ_DE_DHL_Paket_Domestic_DE_德国仓 | AH5: OZ_DE_法兰2仓 | AO5: Desumidificador AeroDrain D12 | AP5: AeroDrain WiFi除湿机_12L_欧版
B6: 606785493240 | C6: 167739312226332841-1 | D6: 947270 | E6: VSE-ADD12-EU | F6: 1 | G6: FB4 | H6: DE_DHL_RETURN_L | I6: 2026-04-01 14:50:27 | J6: 0 | K6: 12.5 | L6: GRS_配送_其它费 | M6: 燃油附加费 | N6: 0 | O6: EUR | P6: 0.04 | Q6: 0 | R6: 0.04 | S6: 0 | T6: 0.04 | Z6: 德国法兰克福2仓 | AA6: v6 | AC6: 00340434648320294268 | AD6: DE | AE6: 99974 | AF6: 55459 | AN6: 【燃油率:0.0125】 | AO6: Desumidificador AeroDrain D12 | AP6: AeroDrain WiFi除湿机_12L_欧版
B7: 606785550265 | C7: 167831206272971807-1 | D7: 947270 | E7: VSFD6500-EU | F7: 1 | G7: FB4 | H7: DE_DHL_RETURN_L | I7: 2026-04-01 15:19:37 | J7: 11 | K7: 11 | L7: FB4尾程 | M7: 高速公路费 | N7: 0 | O7: EUR | P7: 0.19 | Q7: 0 | R7: 0.19 | S7: 0 | T7: 0.19 | X7: 千克 | Y7: 11 | Z7: 德国法兰克福2仓 | AA7: PQ_F1127_20260101 | AC7: 00340434648320294275 | AD7: DE | AE7: 39179 | AF7: 55459 | AO7: VSFD6500 630W | AP7: 欧规 VSFD6500可拆卸630W LED灯(加远红,紫外,串联)
B8: 606785550265 | C8: 167831206272971807-1 | D8: 947270 | E8: VSFD6500-EU | F8: 1 | G8: FB4 | H8: DE_DHL_RETURN_L | I8: 2026-04-01 15:19:37 | J8: 11 | K8: 11 | L8: FB4尾程 | M8: 回邮运费 | N8: 0 | O8: EUR | P8: 4.11 | Q8: 0 | R8: 3.37 | S8: 0 | T8: 3.37 | X8: 千克 | Y8: 11 | Z8: 德国法兰克福2仓 | AA8: PQ_F1127_20260101 | AC8: 00340434648320294275 | AD8: DE | AE8: 39179 | AF8: 55459 | AG8: PZ_DE_DHL_Paket_Domestic_DE_德国仓 | AH8: OZ_DE_法兰2仓 | AO8: VSFD6500 630W | AP8: 欧规 VSFD6500可拆卸630W LED灯(加远红,紫外,串联)
B9: 606785550265 | C9: 167831206272971807-1 | D9: 947270 | E9: VSFD6500-EU | F9: 1 | G9: FB4 | H9: DE_DHL_RETURN_L | I9: 2026-04-01 15:19:37 | J9: 0 | K9: 11 | L9: GRS_配送_其它费 | M9: 燃油附加费 | N9: 0 | O9: EUR | P9: 0.04 | Q9: 0 | R9: 0.04 | S9: 0 | T9: 0.04 | Z9: 德国法兰克福2仓 | AA9: v6 | AC9: 00340434648320294275 | AD9: DE | AE9: 39179 | AF9: 55459 | AN9: 【燃油率:0.0125】 | AO9: VSFD6500 630W | AP9: 欧规 VSFD6500可拆卸630W LED灯(加远红,紫外,串联)
B10: 606786902873 | C10: 01-14446-00032 | D10: 947270 | E10: VSA150SE-E25-EU | F10: 1 | G10: FB4 | H10: DE_DHL_RETURN_L | I10: 2026-04-02 10:54:07 | J10: 3.2 | K10: 3.17 | L10: FB4尾程 | M10: 高速公路费 | N10: 0 | O10: EUR | P10: 0.19 | Q10: 0 | R10: 0.19 | S10: 0 | T10: 0.19 | X10: 千克 | Y10: 3.17 | Z10: 德国法兰克福2仓 | AA10: PQ_F1127_20260101 | AC10: 00340434648320296804 | AD10: DE | AE10: 32423 | AF10: 55459 | AO10: AeroLight A150SE, LED Grow Light 150W with Integrated Circulation Fan & GrowHub Controller E25
B11: 606786902873 | C11: 01-14446-00032 | D11: 947270 | E11: VSA150SE-E25-EU | F11: 1 | G11: FB4 | H11: DE_DHL_RETURN_L | I11: 2026-04-02 10:54:07 | J11: 3.2 | K11: 3.17 | L11: FB4尾程 | M11: 回邮运费 | N11: 0 | O11: EUR | P11: 4.11 | Q11: 0 | R11: 3.37 | S11: 0 | T11: 3.37 | X11: 千克 | Y11: 3.17 | Z11: 德国法兰克福2仓 | AA11: PQ_F1127_20260101 | AC11: 00340434648320296804 | AD11: DE | AE11: 32423 | AF11: 55459 | AG11: PZ_DE_DHL_Paket_Domestic_DE_德国仓 | AH11: OZ_DE_法兰2仓 | AO11: AeroLight A150SE, LED Grow Light 150W with Integrated Circulation Fan & GrowHub Controller E25
B12: 606786902873 | C12: 01-14446-00032 | D12: 947270 | E12: VSA150SE-E25-EU | F12: 1 | G12: FB4 | H12: DE_DHL_RETURN_L | I12: 2026-04-02 10:54:07 | J12: 0 | K12: 3.17 | L12: GRS_配送_其它费 | M12: 燃油附加费 | N12: 0 | O12: EUR | P12: 0.04 | Q12: 0 | R12: 0.04 | S12: 0 | T12: 0.04 | Z12: 德国法兰克福2仓 | AA12: v6 | AC12: 00340434648320296804 | AD12: DE | AE12: 32423 | AF12: 55459 | AN12: 【燃油率:0.0125】 | AO12: AeroLight A150SE, LED Grow Light 150W with Integrated Circulation Fan & GrowHub Controller E25
B13: 606788393243 | C13: 09-14428-79871 | D13: 947270 | E13: 330301-EU | F13: 2 | G13: FB4 | H13: DE_DHL_RETURN_L | I13: 2026-04-03 10:22:50 | J13: 1 | K13: 0.91 | L13: FB4尾程 | M13: 高速公路费 | N13: 0 | O13: EUR | P13: 0.19 | Q13: 0 | R13: 0.19 | S13: 0 | T13: 0.19 | X13: 千克 | Y13: 0.91 | Z13: 德国法兰克福2仓 | AA13: PQ_F1127_20260101 | AC13: 00340434648320298990 | AD13: DE | AE13: 15517 | AF13: 55459 | AO13: Dual digital display heating pad 10" x 20.75"
B14: 606788393243 | C14: 09-14428-79871 | D14: 947270 | E14: 330301-EU | F14: 2 | G14: FB4 | H14: DE_DHL_RETURN_L | I14: 2026-04-03 10:22:50 | J14: 1 | K14: 0.91 | L14: FB4尾程 | M14: 回邮运费 | N14: 0 | O14: EUR | P14: 4.11 | Q14: 0 | R14: 3.37 | S14: 0 | T14: 3.37 | X14: 千克 | Y14: 0.91 | Z14: 德国法兰克福2仓 | AA14: PQ_F1127_20260101 | AC14: 00340434648320298990 | AD14: DE | AE14: 15517 | AF14: 55459 | AG14: PZ_DE_DHL_Paket_Domestic_DE_德国仓 | AH14: OZ_DE_法兰2仓 | AO14: Dual digital display heating pad 10" x 20.75"
B15: 606788393243 | C15: 09-14428-79871 | D15: 947270 | E15: 330301-EU | F15: 2 | G15: FB4 | H15: DE_DHL_RETURN_L | I15: 2026-04-03 10:22:50 | J15: 0 | K15: 0.91 | L15: GRS_配送_其它费 | M15: 燃油附加费 | N15: 0 | O15: EUR | P15: 0.04 | Q15: 0 | R15: 0.04 | S15: 0 | T15: 0.04 | Z15: 德国法兰克福2仓 | AA15: v6 | AC15: 00340434648320298990 | AD15: DE | AE15: 15517 | AF15: 55459 | AN15: 【燃油率:0.0125】 | AO15: Dual digital display heating pad 10" x 20.75"
B16: 606788555781 | C16: 302-0146966-3921961(606788555781) | D16: 947270 | E16: VSF-AWD4X2-EU | F16: 1 | G16: FB4 | H16: DE_DHL_RETURN_L | I16: 2026-04-03 11:37:09 | J16: 0 | K16: 0.61 | L16: FB4尾程 | M16: 高速公路费 | N16: 0 | O16: EUR | P16: 0 | Q16: 0 | R16: 0 | S16: 0 | T16: 0 | X16: 千克 | Y16: 0 | Z16: 德国法兰克福2仓 | AA16: PQ_F1127_20260101 | AD16: DE | AE16: 42369 | AF16: 55459 | AK16: 是 | AO16: AeroWave D4, 4” Grow Tent Clip Fan with Detachable Hook
B17: 606788555781 | C17: 302-0146966-3921961(606788555781) | D17: 947270 | E17: VSF-AWD4X2-EU | F17: 1 | G17: FB4 | H17: DE_DHL_RETURN_L | I17: 2026-04-03 11:37:09 | J17: 0 | K17: 0.61 | L17: FB4尾程 | M17: 回邮运费 | N17: 0 | O17: EUR | P17: 0 | Q17: 0 | R17: 0 | S17: 0 | T17: 0 | X17: 千克 | Y17: 0 | Z17: 德国法兰克福2仓 | AA17: PQ_F1127_20260101 | AD17: DE | AE17: 42369 | AF17: 55459 | AK17: 是 | AO17: AeroWave D4, 4” Grow Tent Clip Fan with Detachable Hook
B18: 606788555781 | C18: 302-0146966-3921961(606788555781) | D18: 947270 | E18: VSF-AWD4X2-EU | F18: 1 | G18: FB4 | H18: DE_DHL_RETURN_L | I18: 2026-04-03 11:37:09 | J18: 0 | K18: 0.61 | L18: GRS_配送_其它费 | M18: 燃油附加费 | N18: 0 | O18: EUR | P18: 0 | Q18: 0 | R18: 0 | S18: 0 | T18: 0 | Z18: 德国法兰克福2仓 | AA18: v6 | AD18: DE | AE18: 42369 | AF18: 55459 | AK18: 是 | AN18: 【燃油率:0.0125】 | AO18: AeroWave D4, 4” Grow Tent Clip Fan with Detachable Hook
B19: 606788565041 | C19: 302-0146966-3921961 | D19: 947270 | E19: VSF-AWD4X2-EU | F19: 1 | G19: FB4 | H19: DE_DHL_RETURN_L | I19: 2026-04-03 11:42:25 | J19: 0.7 | K19: 0.61 | L19: FB4尾程 | M19: 高速公路费 | N19: 0 | O19: EUR | P19: 0.19 | Q19: 0 | R19: 0.19 | S19: 0 | T19: 0.19 | X19: 千克 | Y19: 0.61 | Z19: 德国法兰克福2仓 | AA19: PQ_F1127_20260101 | AC19: 00340434648320299072 | AD19: DE | AE19: 42369 | AF19: 55459 | AO19: AeroWave D4, 4” Grow Tent Clip Fan with Detachable Hook
B20: 606788565041 | C20: 302-0146966-3921961 | D20: 947270 | E20: VSF-AWD4X2-EU | F20: 1 | G20: FB4 | H20: DE_DHL_RETURN_L | I20: 2026-04-03 11:42:25 | J20: 0.7 | K20: 0.61 | L20: FB4尾程 | M20: 回邮运费 | N20: 0 | O20: EUR | P20: 4.11 | Q20: 0 | R20: 3.37 | S20: 0 | T20: 3.37 | X20: 千克 | Y20: 0.61 | Z20: 德国法兰克福2仓 | AA20: PQ_F1127_20260101 | AC20: 00340434648320299072 | AD20: DE | AE20: 42369 | AF20: 55459 | AG20: PZ_DE_DHL_Paket_Domestic_DE_德国仓 | AH20: OZ_DE_法兰2仓 | AO20: AeroWave D4, 4” Grow Tent Clip Fan with Detachable Hook
B21: 606788565041 | C21: 302-0146966-3921961 | D21: 947270 | E21: VSF-AWD4X2-EU | F21: 1 | G21: FB4 | H21: DE_DHL_RETURN_L | I21: 2026-04-03 11:42:25 | J21: 0 | K21: 0.61 | L21: GRS_配送_其它费 | M21: 燃油附加费 | N21: 0 | O21: EUR | P21: 0.04 | Q21: 0 | R21: 0.04 | S21: 0 | T21: 0.04 | Z21: 德国法兰克福2仓 | AA21: v6 | AC21: 00340434648320299072 | AD21: DE | AE21: 42369 | AF21: 55459 | AN21: 【燃油率:0.0125】 | AO21: AeroWave D4, 4” Grow Tent Clip Fan with Detachable Hook
B22: 606789082979 | C22: 167666197655731804-1 | D22: 947270 | E22: VSL-LL100 | F22: 1 | G22: FB4 | H22: DE_DHL_RETURN_L | I22: 2026-04-03 18:07:13 | J22: 3 | K22: 3 | L22: FB4尾程 | M22: 高速公路费 | N22: 0 | O22: EUR | P22: 0.19 | Q22: 0 | R22: 0.19 | S22: 0 | T22: 0.19 | X22: 千克 | Y22: 3 | Z22: 德国法兰克福2仓 | AA22: PQ_F1127_20260101 | AC22: 00340434648320300815 | AD22: DE | AE22: 44789 | AF22: 55459
B23: 606789082979 | C23: 167666197655731804-1 | D23: 947270 | E23: VSL-LL100 | F23: 1 | G23: FB4 | H23: DE_DHL_RETURN_L | I23: 2026-04-03 18:07:13 | J23: 3 | K23: 3 | L23: FB4尾程 | M23: 回邮运费 | N23: 0 | O23: EUR | P23: 4.11 | Q23: 0 | R23: 3.37 | S23: 0 | T23: 3.37 | X23: 千克 | Y23: 3 | Z23: 德国法兰克福2仓 | AA23: PQ_F1127_20260101 | AC23: 00340434648320300815 | AD23: DE | AE23: 44789 | AF23: 55459 | AG23: PZ_DE_DHL_Paket_Domestic_DE_德国仓 | AH23: OZ_DE_法兰2仓
B24: 606789082979 | C24: 167666197655731804-1 | D24: 947270 | E24: VSL-LL100 | F24: 1 | G24: FB4 | H24: DE_DHL_RETURN_L | I24: 2026-04-03 18:07:13 | J24: 0 | K24: 3 | L24: GRS_配送_其它费 | M24: 燃油附加费 | N24: 0 | O24: EUR | P24: 0.04 | Q24: 0 | R24: 0.04 | S24: 0 | T24: 0.04 | Z24: 德国法兰克福2仓 | AA24: v6 | AC24: 00340434648320300815 | AD24: DE | AE24: 44789 | AF24: 55459 | AN24: 【燃油率:0.0125】
B25: 606790618821 | C25: 19-14421-20177 | D25: 947270 | E25: VSF-AWE6-G2-EU | F25: 1 | G25: FB4 | H25: DE_DHL_RETURN_L | I25: 2026-04-05 11:19:28 | J25: 1.1 | K25: 1.1 | L25: FB4尾程 | M25: 高速公路费 | N25: 0 | O25: EUR | P25: 0.19 | Q25: 0 | R25: 0.19 | S25: 0 | T25: 0.19 | X25: 千克 | Y25: 1.1 | Z25: 德国法兰克福2仓 | AA25: PQ_F1127_20260101 | AC25: 00340434648320301911 | AD25: DE | AE25: 37154 | AF25: 55459 | AO25: AeroWave E6 Grow Tent Fan 6”
